[2026-08-21T04:27:16.303+0000] {local_task_job_runner.py:120} INFO - ::group::Pre task execution logs
[2026-08-21T04:27:16.326+0000] {taskinstance.py:2076} INFO - Dependencies all met for dep_context=non-requeueable deps ti=<TaskInstance: cell_kpi_hourly_anomaly_pipeline.2_qc_hourly_silver scheduled__2025-05-31T18:00:00+00:00 [queued]>
[2026-08-21T04:27:16.341+0000] {taskinstance.py:2076} INFO - Dependencies all met for dep_context=requeueable deps ti=<TaskInstance: cell_kpi_hourly_anomaly_pipeline.2_qc_hourly_silver scheduled__2025-05-31T18:00:00+00:00 [queued]>
[2026-08-21T04:27:16.342+0000] {taskinstance.py:2306} INFO - Starting attempt 1 of 2
[2026-08-21T04:27:16.364+0000] {taskinstance.py:2330} INFO - Executing <Task(SparkSubmitOperator): 2_qc_hourly_silver> on 2025-05-31 18:00:00+00:00
[2026-08-21T04:27:16.377+0000] {standard_task_runner.py:63} INFO - Started process 6008 to run task
[2026-08-21T04:27:16.384+0000] {standard_task_runner.py:90} INFO - Running: ['***', 'tasks', 'run', 'cell_kpi_hourly_anomaly_pipeline', '2_qc_hourly_silver', 'scheduled__2025-05-31T18:00:00+00:00', '--job-id', '55', '--raw', '--subdir', 'DAGS_FOLDER/cell_kpi_hourly_anomaly.py', '--cfg-path', '/tmp/tmpaejnjv2z']
[2026-08-21T04:27:16.387+0000] {standard_task_runner.py:91} INFO - Job 55: Subtask 2_qc_hourly_silver
[2026-08-21T04:27:16.457+0000] {task_command.py:426} INFO - Running <TaskInstance: cell_kpi_hourly_anomaly_pipeline.2_qc_hourly_silver scheduled__2025-05-31T18:00:00+00:00 [running]> on host c90a551abb73
[2026-08-21T04:27:16.534+0000] {logging_mixin.py:188} WARNING - /home/***/.local/lib/python3.10/site-packages/***/utils/context.py:212 AirflowContextDeprecationWarning: Accessing 'execution_date' from the template is deprecated and will be removed in a future version. Please use 'data_interval_start' or 'logical_date' instead.
[2026-08-21T04:27:16.583+0000] {taskinstance.py:2648} INFO - Exporting env vars: AIRFLOW_CTX_DAG_OWNER='data_engineer_team' AIRFLOW_CTX_DAG_ID='cell_kpi_hourly_anomaly_pipeline' AIRFLOW_CTX_TASK_ID='2_qc_hourly_silver' AIRFLOW_CTX_EXECUTION_DATE='2025-05-31T18:00:00+00:00' AIRFLOW_CTX_TRY_NUMBER='1' AIRFLOW_CTX_DAG_RUN_ID='scheduled__2025-05-31T18:00:00+00:00'
[2026-08-21T04:27:16.586+0000] {taskinstance.py:430} INFO - ::endgroup::
[2026-08-21T04:27:16.625+0000] {base.py:84} INFO - Using connection ID 'spark-master' for task execution.
[2026-08-21T04:27:16.627+0000] {spark_submit.py:401} INFO - Spark-Submit cmd: spark-submit --master spark://spark-master:7077 --name arrow-spark --deploy-mode client /opt/spark_scripts/2_qc_cell_kpi.py --target_date_hour 2025-06-01-01
[2026-08-21T04:27:16.827+0000] {spark_submit.py:571} INFO - /home/***/.local/lib/python3.10/site-packages/pyspark/bin/load-spark-env.sh: line 68: ps: command not found
[2026-08-21T04:27:21.241+0000] {spark_submit.py:571} INFO - python3: can't open file '/opt/spark_scripts/2_qc_cell_kpi.py': [Errno 2] No such file or directory
[2026-08-21T04:27:21.270+0000] {spark_submit.py:571} INFO - 26/08/21 04:27:21 INFO ShutdownHookManager: Shutdown hook called
[2026-08-21T04:27:21.278+0000] {spark_submit.py:571} INFO - 26/08/21 04:27:21 INFO ShutdownHookManager: Deleting directory /tmp/spark-6f54d5a9-990b-4441-8808-e0c4d8fe9093
[2026-08-21T04:27:21.340+0000] {taskinstance.py:441} INFO - ::group::Post task execution logs
[2026-08-21T04:27:21.352+0000] {taskinstance.py:2905} ERROR - Task failed with exception
Traceback (most recent call last):
  File "/home/airflow/.local/lib/python3.10/site-packages/airflow/models/taskinstance.py", line 465, in _execute_task
    result = _execute_callable(context=context, **execute_callable_kwargs)
  File "/home/airflow/.local/lib/python3.10/site-packages/airflow/models/taskinstance.py", line 432, in _execute_callable
    return execute_callable(context=context, **execute_callable_kwargs)
  File "/home/airflow/.local/lib/python3.10/site-packages/airflow/models/baseoperator.py", line 400, in wrapper
    return func(self, *args, **kwargs)
  File "/home/airflow/.local/lib/python3.10/site-packages/airflow/providers/apache/spark/operators/spark_submit.py", line 174, in execute
    self._hook.submit(self.application)
  File "/home/airflow/.local/lib/python3.10/site-packages/airflow/providers/apache/spark/hooks/spark_submit.py", line 502, in submit
    raise AirflowException(
airflow.exceptions.AirflowException: Cannot execute: spark-submit --master spark://spark-master:7077 --name arrow-spark --deploy-mode client /opt/spark_scripts/2_qc_cell_kpi.py --target_date_hour 2025-06-01-01. Error code is: 2.
[2026-08-21T04:27:21.358+0000] {taskinstance.py:1206} INFO - Marking task as UP_FOR_RETRY. dag_id=cell_kpi_hourly_anomaly_pipeline, task_id=2_qc_hourly_silver, run_id=scheduled__2025-05-31T18:00:00+00:00, execution_date=20250531T180000, start_date=20260821T042716, end_date=20260821T042721
[2026-08-21T04:27:21.372+0000] {standard_task_runner.py:110} ERROR - Failed to execute job 55 for task 2_qc_hourly_silver (Cannot execute: spark-submit --master spark://spark-master:7077 --name arrow-spark --deploy-mode client /opt/spark_scripts/2_qc_cell_kpi.py --target_date_hour 2025-06-01-01. Error code is: 2.; 6008)
[2026-08-21T04:27:21.408+0000] {local_task_job_runner.py:240} INFO - Task exited with return code 1
[2026-08-21T04:27:21.423+0000] {taskinstance.py:3498} INFO - 0 downstream tasks scheduled from follow-on schedule check
[2026-08-21T04:27:21.425+0000] {local_task_job_runner.py:222} INFO - ::endgroup::
[2026-08-21T04:34:22.612+0000] {local_task_job_runner.py:120} INFO - ::group::Pre task execution logs
[2026-08-21T04:34:22.637+0000] {taskinstance.py:2076} INFO - Dependencies all met for dep_context=non-requeueable deps ti=<TaskInstance: cell_kpi_hourly_anomaly_pipeline.2_qc_hourly_silver scheduled__2025-05-31T18:00:00+00:00 [queued]>
[2026-08-21T04:34:22.649+0000] {taskinstance.py:2076} INFO - Dependencies all met for dep_context=requeueable deps ti=<TaskInstance: cell_kpi_hourly_anomaly_pipeline.2_qc_hourly_silver scheduled__2025-05-31T18:00:00+00:00 [queued]>
[2026-08-21T04:34:22.649+0000] {taskinstance.py:2306} INFO - Starting attempt 1 of 2
[2026-08-21T04:34:22.668+0000] {taskinstance.py:2330} INFO - Executing <Task(SparkSubmitOperator): 2_qc_hourly_silver> on 2025-05-31 18:00:00+00:00
[2026-08-21T04:34:22.681+0000] {standard_task_runner.py:63} INFO - Started process 7246 to run task
[2026-08-21T04:34:22.688+0000] {standard_task_runner.py:90} INFO - Running: ['***', 'tasks', 'run', 'cell_kpi_hourly_anomaly_pipeline', '2_qc_hourly_silver', 'scheduled__2025-05-31T18:00:00+00:00', '--job-id', '62', '--raw', '--subdir', 'DAGS_FOLDER/cell_kpi_hourly_anomaly.py', '--cfg-path', '/tmp/tmpxghs7684']
[2026-08-21T04:34:22.691+0000] {standard_task_runner.py:91} INFO - Job 62: Subtask 2_qc_hourly_silver
[2026-08-21T04:34:22.767+0000] {task_command.py:426} INFO - Running <TaskInstance: cell_kpi_hourly_anomaly_pipeline.2_qc_hourly_silver scheduled__2025-05-31T18:00:00+00:00 [running]> on host c90a551abb73
[2026-08-21T04:34:22.894+0000] {logging_mixin.py:188} WARNING - /home/***/.local/lib/python3.10/site-packages/***/utils/context.py:212 AirflowContextDeprecationWarning: Accessing 'execution_date' from the template is deprecated and will be removed in a future version. Please use 'data_interval_start' or 'logical_date' instead.
[2026-08-21T04:34:22.947+0000] {taskinstance.py:2648} INFO - Exporting env vars: AIRFLOW_CTX_DAG_OWNER='data_engineer_team' AIRFLOW_CTX_DAG_ID='cell_kpi_hourly_anomaly_pipeline' AIRFLOW_CTX_TASK_ID='2_qc_hourly_silver' AIRFLOW_CTX_EXECUTION_DATE='2025-05-31T18:00:00+00:00' AIRFLOW_CTX_TRY_NUMBER='1' AIRFLOW_CTX_DAG_RUN_ID='scheduled__2025-05-31T18:00:00+00:00'
[2026-08-21T04:34:22.948+0000] {taskinstance.py:430} INFO - ::endgroup::
[2026-08-21T04:34:22.975+0000] {base.py:84} INFO - Using connection ID 'spark-master' for task execution.
[2026-08-21T04:34:22.976+0000] {spark_submit.py:401} INFO - Spark-Submit cmd: spark-submit --master spark://spark-master:7077 --name arrow-spark --deploy-mode client /opt/spark_scripts/2_qc_hourly_silver.py --target_date_hour 2025-06-01-01
[2026-08-21T04:34:23.133+0000] {spark_submit.py:571} INFO - /home/***/.local/lib/python3.10/site-packages/pyspark/bin/load-spark-env.sh: line 68: ps: command not found
[2026-08-21T04:34:28.301+0000] {spark_submit.py:571} INFO - 26/08/21 04:34:28 INFO SparkContext: Running Spark version 3.5.1
[2026-08-21T04:34:28.304+0000] {spark_submit.py:571} INFO - 26/08/21 04:34:28 INFO SparkContext: OS info Linux, 6.8.0-1052-azure, amd64
[2026-08-21T04:34:28.306+0000] {spark_submit.py:571} INFO - 26/08/21 04:34:28 INFO SparkContext: Java version 17.0.20
[2026-08-21T04:34:28.388+0000] {spark_submit.py:571} INFO - 26/08/21 04:34:28 WARN NativeCodeLoader: Unable to load native-hadoop library for your platform... using builtin-java classes where applicable
[2026-08-21T04:34:28.568+0000] {spark_submit.py:571} INFO - 26/08/21 04:34:28 INFO ResourceUtils: ==============================================================
[2026-08-21T04:34:28.569+0000] {spark_submit.py:571} INFO - 26/08/21 04:34:28 INFO ResourceUtils: No custom resources configured for spark.driver.
[2026-08-21T04:34:28.569+0000] {spark_submit.py:571} INFO - 26/08/21 04:34:28 INFO ResourceUtils: ==============================================================
[2026-08-21T04:34:28.571+0000] {spark_submit.py:571} INFO - 26/08/21 04:34:28 INFO SparkContext: Submitted application: QC_Silver_2025-06-01-01
[2026-08-21T04:34:28.650+0000] {spark_submit.py:571} INFO - 26/08/21 04:34:28 INFO ResourceProfile: Default ResourceProfile created, executor resources: Map(memory -> name: memory, amount: 1024, script: , vendor: , offHeap -> name: offHeap, amount: 0, script: , vendor: ), task resources: Map(cpus -> name: cpus, amount: 1.0)
[2026-08-21T04:34:28.666+0000] {spark_submit.py:571} INFO - 26/08/21 04:34:28 INFO ResourceProfile: Limiting resource is cpu
[2026-08-21T04:34:28.670+0000] {spark_submit.py:571} INFO - 26/08/21 04:34:28 INFO ResourceProfileManager: Added ResourceProfile id: 0
[2026-08-21T04:34:28.723+0000] {spark_submit.py:571} INFO - 26/08/21 04:34:28 INFO SecurityManager: Changing view acls to: ***
[2026-08-21T04:34:28.724+0000] {spark_submit.py:571} INFO - 26/08/21 04:34:28 INFO SecurityManager: Changing modify acls to: ***
[2026-08-21T04:34:28.724+0000] {spark_submit.py:571} INFO - 26/08/21 04:34:28 INFO SecurityManager: Changing view acls groups to:
[2026-08-21T04:34:28.724+0000] {spark_submit.py:571} INFO - 26/08/21 04:34:28 INFO SecurityManager: Changing modify acls groups to:
[2026-08-21T04:34:28.725+0000] {spark_submit.py:571} INFO - 26/08/21 04:34:28 INFO SecurityManager: SecurityManager: authentication disabled; ui acls disabled; users with view permissions: ***; groups with view permissions: EMPTY; users with modify permissions: ***; groups with modify permissions: EMPTY
[2026-08-21T04:34:29.052+0000] {spark_submit.py:571} INFO - 26/08/21 04:34:29 INFO Utils: Successfully started service 'sparkDriver' on port 44919.
[2026-08-21T04:34:29.078+0000] {spark_submit.py:571} INFO - 26/08/21 04:34:29 INFO SparkEnv: Registering MapOutputTracker
[2026-08-21T04:34:29.123+0000] {spark_submit.py:571} INFO - 26/08/21 04:34:29 INFO SparkEnv: Registering BlockManagerMaster
[2026-08-21T04:34:29.130+0000] {spark_submit.py:571} INFO - 26/08/21 04:34:29 INFO BlockManagerMasterEndpoint: Using org.apache.spark.storage.DefaultTopologyMapper for getting topology information
[2026-08-21T04:34:29.131+0000] {spark_submit.py:571} INFO - 26/08/21 04:34:29 INFO BlockManagerMasterEndpoint: BlockManagerMasterEndpoint up
[2026-08-21T04:34:29.134+0000] {spark_submit.py:571} INFO - 26/08/21 04:34:29 INFO SparkEnv: Registering BlockManagerMasterHeartbeat
[2026-08-21T04:34:29.157+0000] {spark_submit.py:571} INFO - 26/08/21 04:34:29 INFO DiskBlockManager: Created local directory at /tmp/blockmgr-d34c0539-3dc1-4067-8183-19bfd48b3fcf
[2026-08-21T04:34:29.168+0000] {spark_submit.py:571} INFO - 26/08/21 04:34:29 INFO MemoryStore: MemoryStore started with capacity 434.4 MiB
[2026-08-21T04:34:29.206+0000] {spark_submit.py:571} INFO - 26/08/21 04:34:29 INFO SparkEnv: Registering OutputCommitCoordinator
[2026-08-21T04:34:29.444+0000] {spark_submit.py:571} INFO - 26/08/21 04:34:29 INFO JettyUtils: Start Jetty 0.0.0.0:4040 for SparkUI
[2026-08-21T04:34:29.547+0000] {spark_submit.py:571} INFO - 26/08/21 04:34:29 WARN Utils: Service 'SparkUI' could not bind on port 4040. Attempting port 4041.
[2026-08-21T04:34:29.559+0000] {spark_submit.py:571} INFO - 26/08/21 04:34:29 INFO Utils: Successfully started service 'SparkUI' on port 4041.
[2026-08-21T04:34:29.832+0000] {spark_submit.py:571} INFO - 26/08/21 04:34:29 INFO StandaloneAppClient$ClientEndpoint: Connecting to master spark://spark-master:7077...
[2026-08-21T04:34:29.941+0000] {spark_submit.py:571} INFO - 26/08/21 04:34:29 INFO TransportClientFactory: Successfully created connection to spark-master/172.18.0.4:7077 after 57 ms (0 ms spent in bootstraps)
[2026-08-21T04:34:30.111+0000] {spark_submit.py:571} INFO - 26/08/21 04:34:30 INFO StandaloneSchedulerBackend: Connected to Spark cluster with app ID app-20260821043430-0021
[2026-08-21T04:34:30.129+0000] {spark_submit.py:571} INFO - 26/08/21 04:34:30 INFO Utils: Successfully started service 'org.apache.spark.network.netty.NettyBlockTransferService' on port 39895.
[2026-08-21T04:34:30.131+0000] {spark_submit.py:571} INFO - 26/08/21 04:34:30 INFO NettyBlockTransferService: Server created on c90a551abb73:39895
[2026-08-21T04:34:30.133+0000] {spark_submit.py:571} INFO - 26/08/21 04:34:30 INFO BlockManager: Using org.apache.spark.storage.RandomBlockReplicationPolicy for block replication policy
[2026-08-21T04:34:30.140+0000] {spark_submit.py:571} INFO - 26/08/21 04:34:30 INFO BlockManagerMaster: Registering BlockManager BlockManagerId(driver, c90a551abb73, 39895, None)
[2026-08-21T04:34:30.143+0000] {spark_submit.py:571} INFO - 26/08/21 04:34:30 INFO BlockManagerMasterEndpoint: Registering block manager c90a551abb73:39895 with 434.4 MiB RAM, BlockManagerId(driver, c90a551abb73, 39895, None)
[2026-08-21T04:34:30.145+0000] {spark_submit.py:571} INFO - 26/08/21 04:34:30 INFO BlockManagerMaster: Registered BlockManager BlockManagerId(driver, c90a551abb73, 39895, None)
[2026-08-21T04:34:30.146+0000] {spark_submit.py:571} INFO - 26/08/21 04:34:30 INFO BlockManager: Initialized BlockManager: BlockManagerId(driver, c90a551abb73, 39895, None)
[2026-08-21T04:34:30.447+0000] {spark_submit.py:571} INFO - 26/08/21 04:34:30 INFO StandaloneSchedulerBackend: SchedulerBackend is ready for scheduling beginning after reached minRegisteredResourcesRatio: 0.0
[2026-08-21T04:34:30.867+0000] {spark_submit.py:571} INFO - Bắt đầu Quality Check (QC) cho ca: 2025-06-01-01
[2026-08-21T04:34:30.996+0000] {spark_submit.py:571} INFO - 26/08/21 04:34:30 INFO SharedState: Setting hive.metastore.warehouse.dir ('null') to the value of spark.sql.warehouse.dir.
[2026-08-21T04:34:31.005+0000] {spark_submit.py:571} INFO - 26/08/21 04:34:31 INFO SharedState: Warehouse path is 'file:/opt/***/spark-warehouse'.
[2026-08-21T04:34:32.608+0000] {spark_submit.py:571} INFO - 26/08/21 04:34:32 WARN MetricsConfig: Cannot locate configuration: tried hadoop-metrics2-s3a-file-system.properties,hadoop-metrics2.properties
[2026-08-21T04:34:32.629+0000] {spark_submit.py:571} INFO - 26/08/21 04:34:32 INFO MetricsSystemImpl: Scheduled Metric snapshot period at 10 second(s).
[2026-08-21T04:34:32.629+0000] {spark_submit.py:571} INFO - 26/08/21 04:34:32 INFO MetricsSystemImpl: s3a-file-system metrics system started
[2026-08-21T04:34:33.812+0000] {spark_submit.py:571} INFO - 26/08/21 04:34:33 INFO DelegatingLogStore: LogStore `LogStoreAdapter(io.delta.storage.S3SingleDriverLogStore)` is used for scheme `s3a`
[2026-08-21T04:34:33.905+0000] {spark_submit.py:571} INFO - 26/08/21 04:34:33 INFO DeltaLog: Loading version 1.
[2026-08-21T04:34:36.760+0000] {spark_submit.py:571} INFO - 26/08/21 04:34:36 INFO DeltaLogFileIndex: Created DeltaLogFileIndex(JSON, numFilesInSegment: 2, totalFileSize: 9799)
[2026-08-21T04:34:38.420+0000] {spark_submit.py:571} INFO - 26/08/21 04:34:38 INFO DataSourceStrategy: Pruning directories with:
[2026-08-21T04:34:38.433+0000] {spark_submit.py:571} INFO - 26/08/21 04:34:38 INFO FileSourceStrategy: Pushed Filters:
[2026-08-21T04:34:38.434+0000] {spark_submit.py:571} INFO - 26/08/21 04:34:38 INFO FileSourceStrategy: Post-Scan Filters: ((isnotnull(protocol#11.minReaderVersion) OR isnotnull(metaData#10.id)) OR (isnotnull(commitInfo#12.inCommitTimestamp) AND (version#13L = 1)))
[2026-08-21T04:34:39.427+0000] {spark_submit.py:571} INFO - 26/08/21 04:34:39 INFO CodeGenerator: Code generated in 571.16783 ms
[2026-08-21T04:34:39.667+0000] {spark_submit.py:571} INFO - 26/08/21 04:34:39 INFO MemoryStore: Block broadcast_0 stored as values in memory (estimated size 201.6 KiB, free 434.2 MiB)
[2026-08-21T04:34:39.891+0000] {spark_submit.py:571} INFO - 26/08/21 04:34:39 INFO MemoryStore: Block broadcast_0_piece0 stored as bytes in memory (estimated size 35.0 KiB, free 434.2 MiB)
[2026-08-21T04:34:39.900+0000] {spark_submit.py:571} INFO - 26/08/21 04:34:39 INFO BlockManagerInfo: Added broadcast_0_piece0 in memory on c90a551abb73:39895 (size: 35.0 KiB, free: 434.4 MiB)
[2026-08-21T04:34:39.906+0000] {spark_submit.py:571} INFO - 26/08/21 04:34:39 INFO SparkContext: Created broadcast 0 from $anonfun$recordDeltaOperationInternal$1 at DatabricksLogging.scala:128
[2026-08-21T04:34:39.989+0000] {spark_submit.py:571} INFO - 26/08/21 04:34:39 INFO FileSourceScanExec: Planning scan with bin packing, max size: 4199203 bytes, open cost is considered as scanning 4194304 bytes.
[2026-08-21T04:34:40.583+0000] {spark_submit.py:571} INFO - 26/08/21 04:34:40 INFO SparkContext: Starting job: $anonfun$recordDeltaOperationInternal$1 at DatabricksLogging.scala:128
[2026-08-21T04:34:40.612+0000] {spark_submit.py:571} INFO - 26/08/21 04:34:40 INFO DAGScheduler: Got job 0 ($anonfun$recordDeltaOperationInternal$1 at DatabricksLogging.scala:128) with 2 output partitions
[2026-08-21T04:34:40.617+0000] {spark_submit.py:571} INFO - 26/08/21 04:34:40 INFO DAGScheduler: Final stage: ResultStage 0 ($anonfun$recordDeltaOperationInternal$1 at DatabricksLogging.scala:128)
[2026-08-21T04:34:40.617+0000] {spark_submit.py:571} INFO - 26/08/21 04:34:40 INFO DAGScheduler: Parents of final stage: List()
[2026-08-21T04:34:40.618+0000] {spark_submit.py:571} INFO - 26/08/21 04:34:40 INFO DAGScheduler: Missing parents: List()
[2026-08-21T04:34:40.621+0000] {spark_submit.py:571} INFO - 26/08/21 04:34:40 INFO DAGScheduler: Submitting ResultStage 0 (MapPartitionsRDD[3] at $anonfun$recordDeltaOperationInternal$1 at DatabricksLogging.scala:128), which has no missing parents
[2026-08-21T04:34:40.702+0000] {spark_submit.py:571} INFO - 26/08/21 04:34:40 INFO MemoryStore: Block broadcast_1 stored as values in memory (estimated size 55.2 KiB, free 434.1 MiB)
[2026-08-21T04:34:40.734+0000] {spark_submit.py:571} INFO - 26/08/21 04:34:40 INFO MemoryStore: Block broadcast_1_piece0 stored as bytes in memory (estimated size 17.1 KiB, free 434.1 MiB)
[2026-08-21T04:34:40.735+0000] {spark_submit.py:571} INFO - 26/08/21 04:34:40 INFO BlockManagerInfo: Added broadcast_1_piece0 in memory on c90a551abb73:39895 (size: 17.1 KiB, free: 434.3 MiB)
[2026-08-21T04:34:40.745+0000] {spark_submit.py:571} INFO - 26/08/21 04:34:40 INFO SparkContext: Created broadcast 1 from broadcast at DAGScheduler.scala:1585
[2026-08-21T04:34:40.776+0000] {spark_submit.py:571} INFO - 26/08/21 04:34:40 INFO DAGScheduler: Submitting 2 missing tasks from ResultStage 0 (MapPartitionsRDD[3] at $anonfun$recordDeltaOperationInternal$1 at DatabricksLogging.scala:128) (first 15 tasks are for partitions Vector(0, 1))
[2026-08-21T04:34:40.784+0000] {spark_submit.py:571} INFO - 26/08/21 04:34:40 INFO TaskSchedulerImpl: Adding task set 0.0 with 2 tasks resource profile 0
[2026-08-21T04:34:55.811+0000] {spark_submit.py:571} INFO - 26/08/21 04:34:55 WARN TaskSchedulerImpl: Initial job has not accepted any resources; check your cluster UI to ensure that workers are registered and have sufficient resources
[2026-08-21T04:35:03.817+0000] {spark_submit.py:571} INFO - 26/08/21 04:35:03 INFO StandaloneAppClient$ClientEndpoint: Executor added: app-20260821043430-0021/0 on worker-20260821021253-172.18.0.6-39045 (172.18.0.6:39045) with 2 core(s)
[2026-08-21T04:35:03.819+0000] {spark_submit.py:571} INFO - 26/08/21 04:35:03 INFO StandaloneSchedulerBackend: Granted executor ID app-20260821043430-0021/0 on hostPort 172.18.0.6:39045 with 2 core(s), 1024.0 MiB RAM
[2026-08-21T04:35:03.821+0000] {spark_submit.py:571} INFO - 26/08/21 04:35:03 INFO StandaloneAppClient$ClientEndpoint: Executor added: app-20260821043430-0021/1 on worker-20260821021253-172.18.0.7-44957 (172.18.0.7:44957) with 2 core(s)
[2026-08-21T04:35:03.821+0000] {spark_submit.py:571} INFO - 26/08/21 04:35:03 INFO StandaloneSchedulerBackend: Granted executor ID app-20260821043430-0021/1 on hostPort 172.18.0.7:44957 with 2 core(s), 1024.0 MiB RAM
[2026-08-21T04:35:03.948+0000] {spark_submit.py:571} INFO - 26/08/21 04:35:03 INFO StandaloneAppClient$ClientEndpoint: Executor updated: app-20260821043430-0021/1 is now RUNNING
[2026-08-21T04:35:03.952+0000] {spark_submit.py:571} INFO - 26/08/21 04:35:03 INFO StandaloneAppClient$ClientEndpoint: Executor updated: app-20260821043430-0021/0 is now RUNNING
[2026-08-21T04:35:08.036+0000] {spark_submit.py:571} INFO - 26/08/21 04:35:08 INFO StandaloneSchedulerBackend$StandaloneDriverEndpoint: Registered executor NettyRpcEndpointRef(spark-client://Executor) (172.18.0.6:45820) with ID 0,  ResourceProfileId 0
[2026-08-21T04:35:08.042+0000] {spark_submit.py:571} INFO - 26/08/21 04:35:08 INFO StandaloneSchedulerBackend$StandaloneDriverEndpoint: Registered executor NettyRpcEndpointRef(spark-client://Executor) (172.18.0.7:48736) with ID 1,  ResourceProfileId 0
[2026-08-21T04:35:08.147+0000] {spark_submit.py:571} INFO - 26/08/21 04:35:08 INFO BlockManagerMasterEndpoint: Registering block manager 172.18.0.7:35755 with 434.4 MiB RAM, BlockManagerId(1, 172.18.0.7, 35755, None)
[2026-08-21T04:35:08.198+0000] {spark_submit.py:571} INFO - 26/08/21 04:35:08 INFO BlockManagerMasterEndpoint: Registering block manager 172.18.0.6:36781 with 434.4 MiB RAM, BlockManagerId(0, 172.18.0.6, 36781, None)
[2026-08-21T04:35:08.304+0000] {spark_submit.py:571} INFO - 26/08/21 04:35:08 INFO TaskSetManager: Starting task 0.0 in stage 0.0 (TID 0) (172.18.0.6, executor 0, partition 0, PROCESS_LOCAL, 8295 bytes)
[2026-08-21T04:35:08.309+0000] {spark_submit.py:571} INFO - 26/08/21 04:35:08 INFO TaskSetManager: Starting task 1.0 in stage 0.0 (TID 1) (172.18.0.6, executor 0, partition 1, PROCESS_LOCAL, 8295 bytes)
[2026-08-21T04:35:08.671+0000] {spark_submit.py:571} INFO - 26/08/21 04:35:08 INFO BlockManagerInfo: Added broadcast_1_piece0 in memory on 172.18.0.6:36781 (size: 17.1 KiB, free: 434.4 MiB)
[2026-08-21T04:35:10.257+0000] {spark_submit.py:571} INFO - 26/08/21 04:35:10 INFO BlockManagerInfo: Added broadcast_0_piece0 in memory on 172.18.0.6:36781 (size: 35.0 KiB, free: 434.3 MiB)
[2026-08-21T04:35:12.345+0000] {spark_submit.py:571} INFO - 26/08/21 04:35:12 INFO TaskSetManager: Finished task 0.0 in stage 0.0 (TID 0) in 4064 ms on 172.18.0.6 (executor 0) (1/2)
[2026-08-21T04:35:12.347+0000] {spark_submit.py:571} INFO - 26/08/21 04:35:12 INFO TaskSetManager: Finished task 1.0 in stage 0.0 (TID 1) in 4038 ms on 172.18.0.6 (executor 0) (2/2)
[2026-08-21T04:35:12.347+0000] {spark_submit.py:571} INFO - 26/08/21 04:35:12 INFO TaskSchedulerImpl: Removed TaskSet 0.0, whose tasks have all completed, from pool
[2026-08-21T04:35:12.354+0000] {spark_submit.py:571} INFO - 26/08/21 04:35:12 INFO DAGScheduler: ResultStage 0 ($anonfun$recordDeltaOperationInternal$1 at DatabricksLogging.scala:128) finished in 31.682 s
[2026-08-21T04:35:12.357+0000] {spark_submit.py:571} INFO - 26/08/21 04:35:12 INFO DAGScheduler: Job 0 is finished. Cancelling potential speculative or zombie tasks for this job
[2026-08-21T04:35:12.358+0000] {spark_submit.py:571} INFO - 26/08/21 04:35:12 INFO TaskSchedulerImpl: Killing all running tasks in stage 0: Stage finished
[2026-08-21T04:35:12.360+0000] {spark_submit.py:571} INFO - 26/08/21 04:35:12 INFO DAGScheduler: Job 0 finished: $anonfun$recordDeltaOperationInternal$1 at DatabricksLogging.scala:128, took 31.773903 s
[2026-08-21T04:35:12.450+0000] {spark_submit.py:571} INFO - 26/08/21 04:35:12 INFO CodeGenerator: Code generated in 57.504543 ms
[2026-08-21T04:35:12.541+0000] {spark_submit.py:571} INFO - 26/08/21 04:35:12 INFO Snapshot: [tableId=8a010e13-1aa6-4954-8e7c-550e19874b81] Created snapshot Snapshot(path=s3a://bronze/cell_kpi_raw/_delta_log, version=1, metadata=Metadata(553802dd-42b6-4cf1-8af2-e0916230ea16,null,null,Format(parquet,Map()),{"type":"struct","fields":[{"name":"enb_name","type":"string","nullable":true,"metadata":{}},{"name":"cell_name","type":"string","nullable":true,"metadata":{}},{"name":"date_hour","type":"string","nullable":true,"metadata":{}},{"name":"dl_traffic_gb","type":"double","nullable":true,"metadata":{}},{"name":"ul_traffic_gb","type":"double","nullable":true,"metadata":{}},{"name":"total_traffic_gb","type":"double","nullable":true,"metadata":{}},{"name":"max_rrc_connected_user","type":"integer","nullable":true,"metadata":{}},{"name":"ul_prb","type":"double","nullable":true,"metadata":{}},{"name":"ul_prb_used","type":"double","nullable":true,"metadata":{}},{"name":"ul_prb_available_total","type":"double","nullable":true,"metadata":{}},{"name":"dl_prb","type":"double","nullable":true,"metadata":{}},{"name":"dl_prb_used","type":"double","nullable":true,"metadata":{}},{"name":"dl_prb_available_total","type":"double","nullable":true,"metadata":{}},{"name":"sector","type":"string","nullable":true,"metadata":{}},{"name":"azimuth","type":"integer","nullable":true,"metadata":{}},{"name":"cell_type","type":"string","nullable":true,"metadata":{}},{"name":"x","type":"double","nullable":true,"metadata":{}},{"name":"y","type":"double","nullable":true,"metadata":{}},{"name":"date","type":"string","nullable":true,"metadata":{}},{"name":"hour","type":"string","nullable":true,"metadata":{}}]},List(date, hour),Map(),Some(1787286784873)), logSegment=LogSegment(s3a://bronze/cell_kpi_raw/_delta_log,1,WrappedArray(S3AFileStatus{path=s3a://bronze/cell_kpi_raw/_delta_log/00000000000000000000.json; isDirectory=false; length=5821; replication=1; blocksize=33554432; modification_time=1787286797585; access_time=0; owner=***; group=***; permission=rw-rw-rw-; isSymlink=false; hasAcl=false; isEncrypted=true; isErasureCoded=false} isEmptyDirectory=FALSE eTag=75575b1ec5f43e5c51e4644a250c1bf4 versionId=null, S3AFileStatus{path=s3a://bronze/cell_kpi_raw/_delta_log/00000000000000000001.json; isDirectory=false; length=3978; replication=1; blocksize=33554432; modification_time=1787286860216; access_time=0; owner=***; group=***; permission=rw-rw-rw-; isSymlink=false; hasAcl=false; isEncrypted=true; isErasureCoded=false} isEmptyDirectory=FALSE eTag=4b99acafbc48768b6984bd481eec7d46 versionId=null),org.apache.spark.sql.delta.EmptyCheckpointProvider$@2fcaeb49,1787286860216), checksumOpt=None)
[2026-08-21T04:35:12.566+0000] {spark_submit.py:571} INFO - 26/08/21 04:35:12 INFO DeltaLog: Updated snapshot to Snapshot(path=s3a://bronze/cell_kpi_raw/_delta_log, version=1, metadata=Metadata(553802dd-42b6-4cf1-8af2-e0916230ea16,null,null,Format(parquet,Map()),{"type":"struct","fields":[{"name":"enb_name","type":"string","nullable":true,"metadata":{}},{"name":"cell_name","type":"string","nullable":true,"metadata":{}},{"name":"date_hour","type":"string","nullable":true,"metadata":{}},{"name":"dl_traffic_gb","type":"double","nullable":true,"metadata":{}},{"name":"ul_traffic_gb","type":"double","nullable":true,"metadata":{}},{"name":"total_traffic_gb","type":"double","nullable":true,"metadata":{}},{"name":"max_rrc_connected_user","type":"integer","nullable":true,"metadata":{}},{"name":"ul_prb","type":"double","nullable":true,"metadata":{}},{"name":"ul_prb_used","type":"double","nullable":true,"metadata":{}},{"name":"ul_prb_available_total","type":"double","nullable":true,"metadata":{}},{"name":"dl_prb","type":"double","nullable":true,"metadata":{}},{"name":"dl_prb_used","type":"double","nullable":true,"metadata":{}},{"name":"dl_prb_available_total","type":"double","nullable":true,"metadata":{}},{"name":"sector","type":"string","nullable":true,"metadata":{}},{"name":"azimuth","type":"integer","nullable":true,"metadata":{}},{"name":"cell_type","type":"string","nullable":true,"metadata":{}},{"name":"x","type":"double","nullable":true,"metadata":{}},{"name":"y","type":"double","nullable":true,"metadata":{}},{"name":"date","type":"string","nullable":true,"metadata":{}},{"name":"hour","type":"string","nullable":true,"metadata":{}}]},List(date, hour),Map(),Some(1787286784873)), logSegment=LogSegment(s3a://bronze/cell_kpi_raw/_delta_log,1,WrappedArray(S3AFileStatus{path=s3a://bronze/cell_kpi_raw/_delta_log/00000000000000000000.json; isDirectory=false; length=5821; replication=1; blocksize=33554432; modification_time=1787286797585; access_time=0; owner=***; group=***; permission=rw-rw-rw-; isSymlink=false; hasAcl=false; isEncrypted=true; isErasureCoded=false} isEmptyDirectory=FALSE eTag=75575b1ec5f43e5c51e4644a250c1bf4 versionId=null, S3AFileStatus{path=s3a://bronze/cell_kpi_raw/_delta_log/00000000000000000001.json; isDirectory=false; length=3978; replication=1; blocksize=33554432; modification_time=1787286860216; access_time=0; owner=***; group=***; permission=rw-rw-rw-; isSymlink=false; hasAcl=false; isEncrypted=true; isErasureCoded=false} isEmptyDirectory=FALSE eTag=4b99acafbc48768b6984bd481eec7d46 versionId=null),org.apache.spark.sql.delta.EmptyCheckpointProvider$@2fcaeb49,1787286860216), checksumOpt=None)
[2026-08-21T04:35:12.927+0000] {spark_submit.py:571} INFO - 26/08/21 04:35:12 INFO PrepareDeltaScan: DELTA: Filtering files for query
[2026-08-21T04:35:13.037+0000] {spark_submit.py:571} INFO - 26/08/21 04:35:12 INFO MemoryStore: Block broadcast_2 stored as values in memory (estimated size 201.3 KiB, free 433.9 MiB)
[2026-08-21T04:35:13.091+0000] {spark_submit.py:571} INFO - 26/08/21 04:35:13 INFO MemoryStore: Block broadcast_2_piece0 stored as bytes in memory (estimated size 34.8 KiB, free 433.9 MiB)
[2026-08-21T04:35:13.103+0000] {spark_submit.py:571} INFO - 26/08/21 04:35:13 INFO BlockManagerInfo: Added broadcast_2_piece0 in memory on c90a551abb73:39895 (size: 34.8 KiB, free: 434.3 MiB)
[2026-08-21T04:35:13.105+0000] {spark_submit.py:571} INFO - 26/08/21 04:35:13 INFO SparkContext: Created broadcast 2 from $anonfun$recordDeltaOperationInternal$1 at DatabricksLogging.scala:128
[2026-08-21T04:35:13.144+0000] {spark_submit.py:571} INFO - 26/08/21 04:35:13 INFO BlockManagerInfo: Removed broadcast_1_piece0 on 172.18.0.6:36781 in memory (size: 17.1 KiB, free: 434.4 MiB)
[2026-08-21T04:35:13.173+0000] {spark_submit.py:571} INFO - 26/08/21 04:35:13 INFO BlockManagerInfo: Removed broadcast_1_piece0 on c90a551abb73:39895 in memory (size: 17.1 KiB, free: 434.3 MiB)
[2026-08-21T04:35:14.103+0000] {spark_submit.py:571} INFO - 26/08/21 04:35:14 INFO DataSourceStrategy: Pruning directories with:
[2026-08-21T04:35:14.103+0000] {spark_submit.py:571} INFO - 26/08/21 04:35:14 INFO FileSourceStrategy: Pushed Filters:
[2026-08-21T04:35:14.104+0000] {spark_submit.py:571} INFO - 26/08/21 04:35:14 INFO FileSourceStrategy: Post-Scan Filters:
[2026-08-21T04:35:14.217+0000] {spark_submit.py:571} INFO - 26/08/21 04:35:14 WARN SparkStringUtils: Truncated the string representation of a plan since it was too large. This behavior can be adjusted by setting 'spark.sql.debug.maxToStringFields'.
[2026-08-21T04:35:14.553+0000] {spark_submit.py:571} INFO - 26/08/21 04:35:14 INFO CodeGenerator: Code generated in 197.536239 ms
[2026-08-21T04:35:14.559+0000] {spark_submit.py:571} INFO - 26/08/21 04:35:14 INFO MemoryStore: Block broadcast_3 stored as values in memory (estimated size 201.6 KiB, free 433.7 MiB)
[2026-08-21T04:35:14.570+0000] {spark_submit.py:571} INFO - 26/08/21 04:35:14 INFO MemoryStore: Block broadcast_3_piece0 stored as bytes in memory (estimated size 35.0 KiB, free 433.7 MiB)
[2026-08-21T04:35:14.571+0000] {spark_submit.py:571} INFO - 26/08/21 04:35:14 INFO BlockManagerInfo: Added broadcast_3_piece0 in memory on c90a551abb73:39895 (size: 35.0 KiB, free: 434.3 MiB)
[2026-08-21T04:35:14.578+0000] {spark_submit.py:571} INFO - 26/08/21 04:35:14 INFO SparkContext: Created broadcast 3 from $anonfun$recordDeltaOperationInternal$1 at DatabricksLogging.scala:128
[2026-08-21T04:35:14.580+0000] {spark_submit.py:571} INFO - 26/08/21 04:35:14 INFO FileSourceScanExec: Planning scan with bin packing, max size: 4194304 bytes, open cost is considered as scanning 4194304 bytes.
[2026-08-21T04:35:14.630+0000] {spark_submit.py:571} INFO - 26/08/21 04:35:14 INFO BlockManagerInfo: Removed broadcast_0_piece0 on c90a551abb73:39895 in memory (size: 35.0 KiB, free: 434.3 MiB)
[2026-08-21T04:35:14.639+0000] {spark_submit.py:571} INFO - 26/08/21 04:35:14 INFO BlockManagerInfo: Removed broadcast_0_piece0 on 172.18.0.6:36781 in memory (size: 35.0 KiB, free: 434.4 MiB)
[2026-08-21T04:35:14.701+0000] {spark_submit.py:571} INFO - 26/08/21 04:35:14 INFO DAGScheduler: Registering RDD 7 ($anonfun$recordDeltaOperationInternal$1 at DatabricksLogging.scala:128) as input to shuffle 0
[2026-08-21T04:35:14.708+0000] {spark_submit.py:571} INFO - 26/08/21 04:35:14 INFO DAGScheduler: Got map stage job 1 ($anonfun$recordDeltaOperationInternal$1 at DatabricksLogging.scala:128) with 2 output partitions
[2026-08-21T04:35:14.710+0000] {spark_submit.py:571} INFO - 26/08/21 04:35:14 INFO DAGScheduler: Final stage: ShuffleMapStage 1 ($anonfun$recordDeltaOperationInternal$1 at DatabricksLogging.scala:128)
[2026-08-21T04:35:14.713+0000] {spark_submit.py:571} INFO - 26/08/21 04:35:14 INFO DAGScheduler: Parents of final stage: List()
[2026-08-21T04:35:14.717+0000] {spark_submit.py:571} INFO - 26/08/21 04:35:14 INFO DAGScheduler: Missing parents: List()
[2026-08-21T04:35:14.720+0000] {spark_submit.py:571} INFO - 26/08/21 04:35:14 INFO DAGScheduler: Submitting ShuffleMapStage 1 (MapPartitionsRDD[7] at $anonfun$recordDeltaOperationInternal$1 at DatabricksLogging.scala:128), which has no missing parents
[2026-08-21T04:35:14.750+0000] {spark_submit.py:571} INFO - 26/08/21 04:35:14 INFO MemoryStore: Block broadcast_4 stored as values in memory (estimated size 105.9 KiB, free 433.8 MiB)
[2026-08-21T04:35:14.763+0000] {spark_submit.py:571} INFO - 26/08/21 04:35:14 INFO MemoryStore: Block broadcast_4_piece0 stored as bytes in memory (estimated size 32.7 KiB, free 433.8 MiB)
[2026-08-21T04:35:14.766+0000] {spark_submit.py:571} INFO - 26/08/21 04:35:14 INFO BlockManagerInfo: Added broadcast_4_piece0 in memory on c90a551abb73:39895 (size: 32.7 KiB, free: 434.3 MiB)
[2026-08-21T04:35:14.767+0000] {spark_submit.py:571} INFO - 26/08/21 04:35:14 INFO SparkContext: Created broadcast 4 from broadcast at DAGScheduler.scala:1585
[2026-08-21T04:35:14.769+0000] {spark_submit.py:571} INFO - 26/08/21 04:35:14 INFO DAGScheduler: Submitting 2 missing tasks from ShuffleMapStage 1 (MapPartitionsRDD[7] at $anonfun$recordDeltaOperationInternal$1 at DatabricksLogging.scala:128) (first 15 tasks are for partitions Vector(0, 1))
[2026-08-21T04:35:14.770+0000] {spark_submit.py:571} INFO - 26/08/21 04:35:14 INFO TaskSchedulerImpl: Adding task set 1.0 with 2 tasks resource profile 0
[2026-08-21T04:35:14.773+0000] {spark_submit.py:571} INFO - 26/08/21 04:35:14 INFO TaskSetManager: Starting task 0.0 in stage 1.0 (TID 2) (172.18.0.7, executor 1, partition 0, PROCESS_LOCAL, 8284 bytes)
[2026-08-21T04:35:14.773+0000] {spark_submit.py:571} INFO - 26/08/21 04:35:14 INFO TaskSetManager: Starting task 1.0 in stage 1.0 (TID 3) (172.18.0.6, executor 0, partition 1, PROCESS_LOCAL, 8284 bytes)
[2026-08-21T04:35:14.834+0000] {spark_submit.py:571} INFO - 26/08/21 04:35:14 INFO BlockManagerInfo: Added broadcast_4_piece0 in memory on 172.18.0.6:36781 (size: 32.7 KiB, free: 434.4 MiB)
[2026-08-21T04:35:15.227+0000] {spark_submit.py:571} INFO - 26/08/21 04:35:15 INFO BlockManagerInfo: Added broadcast_4_piece0 in memory on 172.18.0.7:35755 (size: 32.7 KiB, free: 434.4 MiB)
[2026-08-21T04:35:16.786+0000] {spark_submit.py:571} INFO - 26/08/21 04:35:16 INFO BlockManagerInfo: Added broadcast_3_piece0 in memory on 172.18.0.6:36781 (size: 35.0 KiB, free: 434.3 MiB)
[2026-08-21T04:35:18.706+0000] {spark_submit.py:571} INFO - 26/08/21 04:35:18 INFO TaskSetManager: Finished task 1.0 in stage 1.0 (TID 3) in 3931 ms on 172.18.0.6 (executor 0) (1/2)
[2026-08-21T04:35:19.130+0000] {spark_submit.py:571} INFO - 26/08/21 04:35:19 INFO BlockManagerInfo: Added broadcast_3_piece0 in memory on 172.18.0.7:35755 (size: 35.0 KiB, free: 434.3 MiB)
[2026-08-21T04:35:22.625+0000] {spark_submit.py:571} INFO - 26/08/21 04:35:22 INFO TaskSetManager: Finished task 0.0 in stage 1.0 (TID 2) in 7850 ms on 172.18.0.7 (executor 1) (2/2)
[2026-08-21T04:35:22.626+0000] {spark_submit.py:571} INFO - 26/08/21 04:35:22 INFO TaskSchedulerImpl: Removed TaskSet 1.0, whose tasks have all completed, from pool
[2026-08-21T04:35:22.626+0000] {spark_submit.py:571} INFO - 26/08/21 04:35:22 INFO DAGScheduler: ShuffleMapStage 1 ($anonfun$recordDeltaOperationInternal$1 at DatabricksLogging.scala:128) finished in 7.898 s
[2026-08-21T04:35:22.628+0000] {spark_submit.py:571} INFO - 26/08/21 04:35:22 INFO DAGScheduler: looking for newly runnable stages
[2026-08-21T04:35:22.630+0000] {spark_submit.py:571} INFO - 26/08/21 04:35:22 INFO DAGScheduler: running: Set()
[2026-08-21T04:35:22.630+0000] {spark_submit.py:571} INFO - 26/08/21 04:35:22 INFO DAGScheduler: waiting: Set()
[2026-08-21T04:35:22.631+0000] {spark_submit.py:571} INFO - 26/08/21 04:35:22 INFO DAGScheduler: failed: Set()
[2026-08-21T04:35:22.859+0000] {spark_submit.py:571} INFO - 26/08/21 04:35:22 INFO BlockManagerInfo: Removed broadcast_4_piece0 on c90a551abb73:39895 in memory (size: 32.7 KiB, free: 434.3 MiB)
[2026-08-21T04:35:22.864+0000] {spark_submit.py:571} INFO - 26/08/21 04:35:22 INFO BlockManagerInfo: Removed broadcast_4_piece0 on 172.18.0.7:35755 in memory (size: 32.7 KiB, free: 434.4 MiB)
[2026-08-21T04:35:22.865+0000] {spark_submit.py:571} INFO - 26/08/21 04:35:22 INFO BlockManagerInfo: Removed broadcast_4_piece0 on 172.18.0.6:36781 in memory (size: 32.7 KiB, free: 434.4 MiB)
[2026-08-21T04:35:23.288+0000] {spark_submit.py:571} INFO - 26/08/21 04:35:23 INFO CodeGenerator: Generated method too long to be JIT compiled: org.apache.spark.sql.catalyst.expressions.GeneratedClass$GeneratedIteratorForCodegenStage3.serializefromobject_doConsume_0$ is 25072 bytes
[2026-08-21T04:35:23.290+0000] {spark_submit.py:571} INFO - 26/08/21 04:35:23 INFO CodeGenerator: Code generated in 415.898609 ms
[2026-08-21T04:35:23.507+0000] {spark_submit.py:571} INFO - 26/08/21 04:35:23 INFO CodeGenerator: Code generated in 170.611535 ms
[2026-08-21T04:35:24.344+0000] {spark_submit.py:571} INFO - 26/08/21 04:35:24 INFO CodeGenerator: Code generated in 216.662107 ms
[2026-08-21T04:35:24.456+0000] {spark_submit.py:571} INFO - 26/08/21 04:35:24 INFO SparkContext: Starting job: $anonfun$recordDeltaOperationInternal$1 at DatabricksLogging.scala:128
[2026-08-21T04:35:24.461+0000] {spark_submit.py:571} INFO - 26/08/21 04:35:24 INFO DAGScheduler: Got job 2 ($anonfun$recordDeltaOperationInternal$1 at DatabricksLogging.scala:128) with 50 output partitions
[2026-08-21T04:35:24.461+0000] {spark_submit.py:571} INFO - 26/08/21 04:35:24 INFO DAGScheduler: Final stage: ResultStage 3 ($anonfun$recordDeltaOperationInternal$1 at DatabricksLogging.scala:128)
[2026-08-21T04:35:24.462+0000] {spark_submit.py:571} INFO - 26/08/21 04:35:24 INFO DAGScheduler: Parents of final stage: List(ShuffleMapStage 2)
[2026-08-21T04:35:24.465+0000] {spark_submit.py:571} INFO - 26/08/21 04:35:24 INFO DAGScheduler: Missing parents: List()
[2026-08-21T04:35:24.468+0000] {spark_submit.py:571} INFO - 26/08/21 04:35:24 INFO DAGScheduler: Submitting ResultStage 3 (MapPartitionsRDD[16] at $anonfun$recordDeltaOperationInternal$1 at DatabricksLogging.scala:128), which has no missing parents
[2026-08-21T04:35:24.541+0000] {spark_submit.py:571} INFO - 26/08/21 04:35:24 INFO MemoryStore: Block broadcast_5 stored as values in memory (estimated size 689.9 KiB, free 433.3 MiB)
[2026-08-21T04:35:24.551+0000] {spark_submit.py:571} INFO - 26/08/21 04:35:24 INFO MemoryStore: Block broadcast_5_piece0 stored as bytes in memory (estimated size 155.9 KiB, free 433.1 MiB)
[2026-08-21T04:35:24.551+0000] {spark_submit.py:571} INFO - 26/08/21 04:35:24 INFO BlockManagerInfo: Added broadcast_5_piece0 in memory on c90a551abb73:39895 (size: 155.9 KiB, free: 434.2 MiB)
[2026-08-21T04:35:24.556+0000] {spark_submit.py:571} INFO - 26/08/21 04:35:24 INFO SparkContext: Created broadcast 5 from broadcast at DAGScheduler.scala:1585
[2026-08-21T04:35:24.556+0000] {spark_submit.py:571} INFO - 26/08/21 04:35:24 INFO DAGScheduler: Submitting 50 missing tasks from ResultStage 3 (MapPartitionsRDD[16] at $anonfun$recordDeltaOperationInternal$1 at DatabricksLogging.scala:128) (first 15 tasks are for partitions Vector(0, 1, 2, 3, 4, 5, 6, 7, 8, 9, 10, 11, 12, 13, 14))
[2026-08-21T04:35:24.557+0000] {spark_submit.py:571} INFO - 26/08/21 04:35:24 INFO TaskSchedulerImpl: Adding task set 3.0 with 50 tasks resource profile 0
[2026-08-21T04:35:24.572+0000] {spark_submit.py:571} INFO - 26/08/21 04:35:24 INFO TaskSetManager: Starting task 24.0 in stage 3.0 (TID 4) (172.18.0.7, executor 1, partition 24, NODE_LOCAL, 7619 bytes)
[2026-08-21T04:35:24.573+0000] {spark_submit.py:571} INFO - 26/08/21 04:35:24 INFO TaskSetManager: Starting task 0.0 in stage 3.0 (TID 5) (172.18.0.6, executor 0, partition 0, NODE_LOCAL, 7619 bytes)
[2026-08-21T04:35:24.573+0000] {spark_submit.py:571} INFO - 26/08/21 04:35:24 INFO TaskSetManager: Starting task 30.0 in stage 3.0 (TID 6) (172.18.0.7, executor 1, partition 30, NODE_LOCAL, 7619 bytes)
[2026-08-21T04:35:24.573+0000] {spark_submit.py:571} INFO - 26/08/21 04:35:24 INFO TaskSetManager: Starting task 11.0 in stage 3.0 (TID 7) (172.18.0.6, executor 0, partition 11, NODE_LOCAL, 7619 bytes)
[2026-08-21T04:35:24.655+0000] {spark_submit.py:571} INFO - 26/08/21 04:35:24 INFO BlockManagerInfo: Added broadcast_5_piece0 in memory on 172.18.0.6:36781 (size: 155.9 KiB, free: 434.2 MiB)
[2026-08-21T04:35:24.662+0000] {spark_submit.py:571} INFO - 26/08/21 04:35:24 INFO BlockManagerInfo: Added broadcast_5_piece0 in memory on 172.18.0.7:35755 (size: 155.9 KiB, free: 434.2 MiB)
[2026-08-21T04:35:25.383+0000] {spark_submit.py:571} INFO - 26/08/21 04:35:25 INFO MapOutputTrackerMasterEndpoint: Asked to send map output locations for shuffle 0 to 172.18.0.6:45820
[2026-08-21T04:35:25.625+0000] {spark_submit.py:571} INFO - 26/08/21 04:35:25 INFO MapOutputTrackerMasterEndpoint: Asked to send map output locations for shuffle 0 to 172.18.0.7:48736
[2026-08-21T04:35:27.887+0000] {spark_submit.py:571} INFO - 26/08/21 04:35:27 INFO BlockManagerInfo: Added rdd_14_11 in memory on 172.18.0.6:36781 (size: 1152.0 B, free: 434.2 MiB)
[2026-08-21T04:35:27.894+0000] {spark_submit.py:571} INFO - 26/08/21 04:35:27 INFO BlockManagerInfo: Added rdd_14_0 in memory on 172.18.0.6:36781 (size: 1176.0 B, free: 434.2 MiB)
[2026-08-21T04:35:27.973+0000] {spark_submit.py:571} INFO - 26/08/21 04:35:27 INFO BlockManagerInfo: Added rdd_14_24 in memory on 172.18.0.7:35755 (size: 1179.0 B, free: 434.2 MiB)
[2026-08-21T04:35:27.982+0000] {spark_submit.py:571} INFO - 26/08/21 04:35:27 INFO BlockManagerInfo: Added rdd_14_30 in memory on 172.18.0.7:35755 (size: 1157.0 B, free: 434.2 MiB)
[2026-08-21T04:35:28.392+0000] {spark_submit.py:571} INFO - 26/08/21 04:35:28 INFO TaskSetManager: Starting task 42.0 in stage 3.0 (TID 8) (172.18.0.6, executor 0, partition 42, NODE_LOCAL, 7619 bytes)
[2026-08-21T04:35:28.396+0000] {spark_submit.py:571} INFO - 26/08/21 04:35:28 INFO TaskSetManager: Finished task 11.0 in stage 3.0 (TID 7) in 3817 ms on 172.18.0.6 (executor 0) (1/50)
[2026-08-21T04:35:28.412+0000] {spark_submit.py:571} INFO - 26/08/21 04:35:28 INFO TaskSetManager: Starting task 1.0 in stage 3.0 (TID 9) (172.18.0.6, executor 0, partition 1, PROCESS_LOCAL, 7619 bytes)
[2026-08-21T04:35:28.430+0000] {spark_submit.py:571} INFO - 26/08/21 04:35:28 INFO TaskSetManager: Finished task 0.0 in stage 3.0 (TID 5) in 3863 ms on 172.18.0.6 (executor 0) (2/50)
[2026-08-21T04:35:28.547+0000] {spark_submit.py:571} INFO - 26/08/21 04:35:28 INFO TaskSetManager: Starting task 2.0 in stage 3.0 (TID 10) (172.18.0.7, executor 1, partition 2, PROCESS_LOCAL, 7619 bytes)
[2026-08-21T04:35:28.550+0000] {spark_submit.py:571} INFO - 26/08/21 04:35:28 INFO TaskSetManager: Finished task 24.0 in stage 3.0 (TID 4) in 3983 ms on 172.18.0.7 (executor 1) (3/50)
[2026-08-21T04:35:28.585+0000] {spark_submit.py:571} INFO - 26/08/21 04:35:28 INFO TaskSetManager: Starting task 3.0 in stage 3.0 (TID 11) (172.18.0.7, executor 1, partition 3, PROCESS_LOCAL, 7619 bytes)
[2026-08-21T04:35:28.585+0000] {spark_submit.py:571} INFO - 26/08/21 04:35:28 INFO TaskSetManager: Finished task 30.0 in stage 3.0 (TID 6) in 4015 ms on 172.18.0.7 (executor 1) (4/50)
[2026-08-21T04:35:29.008+0000] {spark_submit.py:571} INFO - 26/08/21 04:35:29 INFO BlockManagerInfo: Added rdd_14_1 in memory on 172.18.0.6:36781 (size: 46.0 B, free: 434.2 MiB)
[2026-08-21T04:35:29.051+0000] {spark_submit.py:571} INFO - 26/08/21 04:35:29 INFO TaskSetManager: Starting task 4.0 in stage 3.0 (TID 12) (172.18.0.6, executor 0, partition 4, PROCESS_LOCAL, 7619 bytes)
[2026-08-21T04:35:29.059+0000] {spark_submit.py:571} INFO - 26/08/21 04:35:29 INFO TaskSetManager: Finished task 1.0 in stage 3.0 (TID 9) in 644 ms on 172.18.0.6 (executor 0) (5/50)
[2026-08-21T04:35:29.087+0000] {spark_submit.py:571} INFO - 26/08/21 04:35:29 INFO BlockManagerInfo: Added rdd_14_2 in memory on 172.18.0.7:35755 (size: 46.0 B, free: 434.2 MiB)
[2026-08-21T04:35:29.146+0000] {spark_submit.py:571} INFO - 26/08/21 04:35:29 INFO BlockManagerInfo: Added rdd_14_3 in memory on 172.18.0.7:35755 (size: 46.0 B, free: 434.2 MiB)
[2026-08-21T04:35:29.150+0000] {spark_submit.py:571} INFO - 26/08/21 04:35:29 INFO TaskSetManager: Starting task 5.0 in stage 3.0 (TID 13) (172.18.0.7, executor 1, partition 5, PROCESS_LOCAL, 7619 bytes)
[2026-08-21T04:35:29.162+0000] {spark_submit.py:571} INFO - 26/08/21 04:35:29 INFO TaskSetManager: Finished task 2.0 in stage 3.0 (TID 10) in 613 ms on 172.18.0.7 (executor 1) (6/50)
[2026-08-21T04:35:29.190+0000] {spark_submit.py:571} INFO - 26/08/21 04:35:29 INFO TaskSetManager: Starting task 6.0 in stage 3.0 (TID 14) (172.18.0.7, executor 1, partition 6, PROCESS_LOCAL, 7619 bytes)
[2026-08-21T04:35:29.199+0000] {spark_submit.py:571} INFO - 26/08/21 04:35:29 INFO TaskSetManager: Finished task 3.0 in stage 3.0 (TID 11) in 614 ms on 172.18.0.7 (executor 1) (7/50)
[2026-08-21T04:35:29.375+0000] {spark_submit.py:571} INFO - 26/08/21 04:35:29 INFO BlockManagerInfo: Added rdd_14_4 in memory on 172.18.0.6:36781 (size: 46.0 B, free: 434.2 MiB)
[2026-08-21T04:35:29.423+0000] {spark_submit.py:571} INFO - 26/08/21 04:35:29 INFO TaskSetManager: Starting task 7.0 in stage 3.0 (TID 15) (172.18.0.6, executor 0, partition 7, PROCESS_LOCAL, 7619 bytes)
[2026-08-21T04:35:29.449+0000] {spark_submit.py:571} INFO - 26/08/21 04:35:29 INFO TaskSetManager: Finished task 4.0 in stage 3.0 (TID 12) in 398 ms on 172.18.0.6 (executor 0) (8/50)
[2026-08-21T04:35:29.553+0000] {spark_submit.py:571} INFO - 26/08/21 04:35:29 INFO BlockManagerInfo: Added rdd_14_5 in memory on 172.18.0.7:35755 (size: 46.0 B, free: 434.2 MiB)
[2026-08-21T04:35:29.586+0000] {spark_submit.py:571} INFO - 26/08/21 04:35:29 INFO BlockManagerInfo: Added rdd_14_6 in memory on 172.18.0.7:35755 (size: 46.0 B, free: 434.2 MiB)
[2026-08-21T04:35:29.599+0000] {spark_submit.py:571} INFO - 26/08/21 04:35:29 INFO TaskSetManager: Starting task 8.0 in stage 3.0 (TID 16) (172.18.0.7, executor 1, partition 8, PROCESS_LOCAL, 7619 bytes)
[2026-08-21T04:35:29.606+0000] {spark_submit.py:571} INFO - 26/08/21 04:35:29 INFO TaskSetManager: Finished task 5.0 in stage 3.0 (TID 13) in 457 ms on 172.18.0.7 (executor 1) (9/50)
[2026-08-21T04:35:29.623+0000] {spark_submit.py:571} INFO - 26/08/21 04:35:29 INFO TaskSetManager: Starting task 9.0 in stage 3.0 (TID 17) (172.18.0.7, executor 1, partition 9, PROCESS_LOCAL, 7619 bytes)
[2026-08-21T04:35:29.635+0000] {spark_submit.py:571} INFO - 26/08/21 04:35:29 INFO TaskSetManager: Finished task 6.0 in stage 3.0 (TID 14) in 446 ms on 172.18.0.7 (executor 1) (10/50)
[2026-08-21T04:35:29.920+0000] {spark_submit.py:571} INFO - 26/08/21 04:35:29 INFO BlockManagerInfo: Added rdd_14_7 in memory on 172.18.0.6:36781 (size: 46.0 B, free: 434.2 MiB)
[2026-08-21T04:35:29.954+0000] {spark_submit.py:571} INFO - 26/08/21 04:35:29 INFO TaskSetManager: Starting task 10.0 in stage 3.0 (TID 18) (172.18.0.6, executor 0, partition 10, PROCESS_LOCAL, 7619 bytes)
[2026-08-21T04:35:29.976+0000] {spark_submit.py:571} INFO - 26/08/21 04:35:29 INFO TaskSetManager: Finished task 7.0 in stage 3.0 (TID 15) in 556 ms on 172.18.0.6 (executor 0) (11/50)
[2026-08-21T04:35:30.068+0000] {spark_submit.py:571} INFO - 26/08/21 04:35:30 INFO BlockManagerInfo: Added rdd_14_42 in memory on 172.18.0.6:36781 (size: 699.0 B, free: 434.2 MiB)
[2026-08-21T04:35:30.106+0000] {spark_submit.py:571} INFO - 26/08/21 04:35:30 INFO TaskSetManager: Starting task 12.0 in stage 3.0 (TID 19) (172.18.0.6, executor 0, partition 12, PROCESS_LOCAL, 7619 bytes)
[2026-08-21T04:35:30.118+0000] {spark_submit.py:571} INFO - 26/08/21 04:35:30 INFO TaskSetManager: Finished task 42.0 in stage 3.0 (TID 8) in 1725 ms on 172.18.0.6 (executor 0) (12/50)
[2026-08-21T04:35:30.132+0000] {spark_submit.py:571} INFO - 26/08/21 04:35:30 INFO BlockManagerInfo: Added rdd_14_8 in memory on 172.18.0.7:35755 (size: 46.0 B, free: 434.2 MiB)
[2026-08-21T04:35:30.169+0000] {spark_submit.py:571} INFO - 26/08/21 04:35:30 INFO TaskSetManager: Starting task 13.0 in stage 3.0 (TID 20) (172.18.0.7, executor 1, partition 13, PROCESS_LOCAL, 7619 bytes)
[2026-08-21T04:35:30.188+0000] {spark_submit.py:571} INFO - 26/08/21 04:35:30 INFO TaskSetManager: Finished task 8.0 in stage 3.0 (TID 16) in 590 ms on 172.18.0.7 (executor 1) (13/50)
[2026-08-21T04:35:30.205+0000] {spark_submit.py:571} INFO - 26/08/21 04:35:30 INFO BlockManagerInfo: Added rdd_14_9 in memory on 172.18.0.7:35755 (size: 46.0 B, free: 434.2 MiB)
[2026-08-21T04:35:30.250+0000] {spark_submit.py:571} INFO - 26/08/21 04:35:30 INFO TaskSetManager: Starting task 14.0 in stage 3.0 (TID 21) (172.18.0.7, executor 1, partition 14, PROCESS_LOCAL, 7619 bytes)
[2026-08-21T04:35:30.256+0000] {spark_submit.py:571} INFO - 26/08/21 04:35:30 INFO BlockManagerInfo: Added rdd_14_10 in memory on 172.18.0.6:36781 (size: 46.0 B, free: 434.2 MiB)
[2026-08-21T04:35:30.257+0000] {spark_submit.py:571} INFO - 26/08/21 04:35:30 INFO TaskSetManager: Finished task 9.0 in stage 3.0 (TID 17) in 632 ms on 172.18.0.7 (executor 1) (14/50)
[2026-08-21T04:35:30.305+0000] {spark_submit.py:571} INFO - 26/08/21 04:35:30 INFO BlockManagerInfo: Added rdd_14_12 in memory on 172.18.0.6:36781 (size: 46.0 B, free: 434.2 MiB)
[2026-08-21T04:35:30.315+0000] {spark_submit.py:571} INFO - 26/08/21 04:35:30 INFO TaskSetManager: Starting task 15.0 in stage 3.0 (TID 22) (172.18.0.6, executor 0, partition 15, PROCESS_LOCAL, 7619 bytes)
[2026-08-21T04:35:30.326+0000] {spark_submit.py:571} INFO - 26/08/21 04:35:30 INFO TaskSetManager: Finished task 10.0 in stage 3.0 (TID 18) in 374 ms on 172.18.0.6 (executor 0) (15/50)
[2026-08-21T04:35:30.338+0000] {spark_submit.py:571} INFO - 26/08/21 04:35:30 INFO TaskSetManager: Starting task 16.0 in stage 3.0 (TID 23) (172.18.0.6, executor 0, partition 16, PROCESS_LOCAL, 7619 bytes)
[2026-08-21T04:35:30.343+0000] {spark_submit.py:571} INFO - 26/08/21 04:35:30 INFO TaskSetManager: Finished task 12.0 in stage 3.0 (TID 19) in 244 ms on 172.18.0.6 (executor 0) (16/50)
[2026-08-21T04:35:30.459+0000] {spark_submit.py:571} INFO - 26/08/21 04:35:30 INFO BlockManagerInfo: Added rdd_14_13 in memory on 172.18.0.7:35755 (size: 46.0 B, free: 434.2 MiB)
[2026-08-21T04:35:30.480+0000] {spark_submit.py:571} INFO - 26/08/21 04:35:30 INFO BlockManagerInfo: Added rdd_14_14 in memory on 172.18.0.7:35755 (size: 46.0 B, free: 434.2 MiB)
[2026-08-21T04:35:30.501+0000] {spark_submit.py:571} INFO - 26/08/21 04:35:30 INFO TaskSetManager: Starting task 17.0 in stage 3.0 (TID 24) (172.18.0.7, executor 1, partition 17, PROCESS_LOCAL, 7619 bytes)
[2026-08-21T04:35:30.502+0000] {spark_submit.py:571} INFO - 26/08/21 04:35:30 INFO TaskSetManager: Finished task 13.0 in stage 3.0 (TID 20) in 332 ms on 172.18.0.7 (executor 1) (17/50)
[2026-08-21T04:35:30.536+0000] {spark_submit.py:571} INFO - 26/08/21 04:35:30 INFO TaskSetManager: Starting task 18.0 in stage 3.0 (TID 25) (172.18.0.7, executor 1, partition 18, PROCESS_LOCAL, 7619 bytes)
[2026-08-21T04:35:30.544+0000] {spark_submit.py:571} INFO - 26/08/21 04:35:30 INFO TaskSetManager: Finished task 14.0 in stage 3.0 (TID 21) in 295 ms on 172.18.0.7 (executor 1) (18/50)
[2026-08-21T04:35:30.617+0000] {spark_submit.py:571} INFO - 26/08/21 04:35:30 INFO BlockManagerInfo: Added rdd_14_15 in memory on 172.18.0.6:36781 (size: 46.0 B, free: 434.2 MiB)
[2026-08-21T04:35:30.658+0000] {spark_submit.py:571} INFO - 26/08/21 04:35:30 INFO TaskSetManager: Starting task 19.0 in stage 3.0 (TID 26) (172.18.0.6, executor 0, partition 19, PROCESS_LOCAL, 7619 bytes)
[2026-08-21T04:35:30.669+0000] {spark_submit.py:571} INFO - 26/08/21 04:35:30 INFO BlockManagerInfo: Added rdd_14_16 in memory on 172.18.0.6:36781 (size: 46.0 B, free: 434.2 MiB)
[2026-08-21T04:35:30.669+0000] {spark_submit.py:571} INFO - 26/08/21 04:35:30 INFO TaskSetManager: Finished task 15.0 in stage 3.0 (TID 22) in 351 ms on 172.18.0.6 (executor 0) (19/50)
[2026-08-21T04:35:30.692+0000] {spark_submit.py:571} INFO - 26/08/21 04:35:30 INFO TaskSetManager: Starting task 20.0 in stage 3.0 (TID 27) (172.18.0.6, executor 0, partition 20, PROCESS_LOCAL, 7619 bytes)
[2026-08-21T04:35:30.694+0000] {spark_submit.py:571} INFO - 26/08/21 04:35:30 INFO TaskSetManager: Finished task 16.0 in stage 3.0 (TID 23) in 356 ms on 172.18.0.6 (executor 0) (20/50)
[2026-08-21T04:35:30.753+0000] {spark_submit.py:571} INFO - 26/08/21 04:35:30 INFO BlockManagerInfo: Added rdd_14_17 in memory on 172.18.0.7:35755 (size: 46.0 B, free: 434.2 MiB)
[2026-08-21T04:35:30.770+0000] {spark_submit.py:571} INFO - 26/08/21 04:35:30 INFO BlockManagerInfo: Added rdd_14_18 in memory on 172.18.0.7:35755 (size: 46.0 B, free: 434.2 MiB)
[2026-08-21T04:35:30.770+0000] {spark_submit.py:571} INFO - 26/08/21 04:35:30 INFO TaskSetManager: Starting task 21.0 in stage 3.0 (TID 28) (172.18.0.7, executor 1, partition 21, PROCESS_LOCAL, 7619 bytes)
[2026-08-21T04:35:30.775+0000] {spark_submit.py:571} INFO - 26/08/21 04:35:30 INFO BlockManagerInfo: Added rdd_14_19 in memory on 172.18.0.6:36781 (size: 46.0 B, free: 434.2 MiB)
[2026-08-21T04:35:30.778+0000] {spark_submit.py:571} INFO - 26/08/21 04:35:30 INFO TaskSetManager: Finished task 17.0 in stage 3.0 (TID 24) in 275 ms on 172.18.0.7 (executor 1) (21/50)
[2026-08-21T04:35:30.790+0000] {spark_submit.py:571} INFO - 26/08/21 04:35:30 INFO TaskSetManager: Starting task 22.0 in stage 3.0 (TID 29) (172.18.0.7, executor 1, partition 22, PROCESS_LOCAL, 7619 bytes)
[2026-08-21T04:35:30.815+0000] {spark_submit.py:571} INFO - 26/08/21 04:35:30 INFO TaskSetManager: Finished task 18.0 in stage 3.0 (TID 25) in 280 ms on 172.18.0.7 (executor 1) (22/50)
[2026-08-21T04:35:30.867+0000] {spark_submit.py:571} INFO - 26/08/21 04:35:30 INFO TaskSetManager: Starting task 23.0 in stage 3.0 (TID 30) (172.18.0.6, executor 0, partition 23, PROCESS_LOCAL, 7619 bytes)
[2026-08-21T04:35:30.879+0000] {spark_submit.py:571} INFO - 26/08/21 04:35:30 INFO TaskSetManager: Finished task 19.0 in stage 3.0 (TID 26) in 222 ms on 172.18.0.6 (executor 0) (23/50)
[2026-08-21T04:35:30.982+0000] {spark_submit.py:571} INFO - 26/08/21 04:35:30 INFO BlockManagerInfo: Added rdd_14_20 in memory on 172.18.0.6:36781 (size: 46.0 B, free: 434.2 MiB)
[2026-08-21T04:35:31.010+0000] {spark_submit.py:571} INFO - 26/08/21 04:35:31 INFO TaskSetManager: Starting task 25.0 in stage 3.0 (TID 31) (172.18.0.6, executor 0, partition 25, PROCESS_LOCAL, 7619 bytes)
[2026-08-21T04:35:31.020+0000] {spark_submit.py:571} INFO - 26/08/21 04:35:31 INFO TaskSetManager: Finished task 20.0 in stage 3.0 (TID 27) in 330 ms on 172.18.0.6 (executor 0) (24/50)
[2026-08-21T04:35:31.039+0000] {spark_submit.py:571} INFO - 26/08/21 04:35:31 INFO BlockManagerInfo: Added rdd_14_21 in memory on 172.18.0.7:35755 (size: 46.0 B, free: 434.2 MiB)
[2026-08-21T04:35:31.074+0000] {spark_submit.py:571} INFO - 26/08/21 04:35:31 INFO BlockManagerInfo: Added rdd_14_22 in memory on 172.18.0.7:35755 (size: 46.0 B, free: 434.2 MiB)
[2026-08-21T04:35:31.093+0000] {spark_submit.py:571} INFO - 26/08/21 04:35:31 INFO BlockManagerInfo: Added rdd_14_23 in memory on 172.18.0.6:36781 (size: 46.0 B, free: 434.2 MiB)
[2026-08-21T04:35:31.094+0000] {spark_submit.py:571} INFO - 26/08/21 04:35:31 INFO TaskSetManager: Starting task 26.0 in stage 3.0 (TID 32) (172.18.0.7, executor 1, partition 26, PROCESS_LOCAL, 7619 bytes)
[2026-08-21T04:35:31.094+0000] {spark_submit.py:571} INFO - 26/08/21 04:35:31 INFO TaskSetManager: Finished task 21.0 in stage 3.0 (TID 28) in 324 ms on 172.18.0.7 (executor 1) (25/50)
[2026-08-21T04:35:31.111+0000] {spark_submit.py:571} INFO - 26/08/21 04:35:31 INFO TaskSetManager: Starting task 27.0 in stage 3.0 (TID 33) (172.18.0.7, executor 1, partition 27, PROCESS_LOCAL, 7619 bytes)
[2026-08-21T04:35:31.112+0000] {spark_submit.py:571} INFO - 26/08/21 04:35:31 INFO TaskSetManager: Finished task 22.0 in stage 3.0 (TID 29) in 322 ms on 172.18.0.7 (executor 1) (26/50)
[2026-08-21T04:35:31.170+0000] {spark_submit.py:571} INFO - 26/08/21 04:35:31 INFO TaskSetManager: Starting task 28.0 in stage 3.0 (TID 34) (172.18.0.6, executor 0, partition 28, PROCESS_LOCAL, 7619 bytes)
[2026-08-21T04:35:31.180+0000] {spark_submit.py:571} INFO - 26/08/21 04:35:31 INFO TaskSetManager: Finished task 23.0 in stage 3.0 (TID 30) in 308 ms on 172.18.0.6 (executor 0) (27/50)
[2026-08-21T04:35:31.401+0000] {spark_submit.py:571} INFO - 26/08/21 04:35:31 INFO BlockManagerInfo: Added rdd_14_28 in memory on 172.18.0.6:36781 (size: 46.0 B, free: 434.2 MiB)
[2026-08-21T04:35:31.422+0000] {spark_submit.py:571} INFO - 26/08/21 04:35:31 INFO TaskSetManager: Starting task 29.0 in stage 3.0 (TID 35) (172.18.0.6, executor 0, partition 29, PROCESS_LOCAL, 7619 bytes)
[2026-08-21T04:35:31.423+0000] {spark_submit.py:571} INFO - 26/08/21 04:35:31 INFO TaskSetManager: Finished task 28.0 in stage 3.0 (TID 34) in 250 ms on 172.18.0.6 (executor 0) (28/50)
[2026-08-21T04:35:31.428+0000] {spark_submit.py:571} INFO - 26/08/21 04:35:31 INFO BlockManagerInfo: Added rdd_14_27 in memory on 172.18.0.7:35755 (size: 46.0 B, free: 434.2 MiB)
[2026-08-21T04:35:31.433+0000] {spark_submit.py:571} INFO - 26/08/21 04:35:31 INFO BlockManagerInfo: Added rdd_14_26 in memory on 172.18.0.7:35755 (size: 46.0 B, free: 434.2 MiB)
[2026-08-21T04:35:31.437+0000] {spark_submit.py:571} INFO - 26/08/21 04:35:31 INFO BlockManagerInfo: Added rdd_14_25 in memory on 172.18.0.6:36781 (size: 46.0 B, free: 434.2 MiB)
[2026-08-21T04:35:31.448+0000] {spark_submit.py:571} INFO - 26/08/21 04:35:31 INFO TaskSetManager: Starting task 31.0 in stage 3.0 (TID 36) (172.18.0.7, executor 1, partition 31, PROCESS_LOCAL, 7619 bytes)
[2026-08-21T04:35:31.454+0000] {spark_submit.py:571} INFO - 26/08/21 04:35:31 INFO TaskSetManager: Finished task 27.0 in stage 3.0 (TID 33) in 347 ms on 172.18.0.7 (executor 1) (29/50)
[2026-08-21T04:35:31.463+0000] {spark_submit.py:571} INFO - 26/08/21 04:35:31 INFO TaskSetManager: Starting task 32.0 in stage 3.0 (TID 37) (172.18.0.7, executor 1, partition 32, PROCESS_LOCAL, 7619 bytes)
[2026-08-21T04:35:31.464+0000] {spark_submit.py:571} INFO - 26/08/21 04:35:31 INFO TaskSetManager: Finished task 26.0 in stage 3.0 (TID 32) in 371 ms on 172.18.0.7 (executor 1) (30/50)
[2026-08-21T04:35:31.467+0000] {spark_submit.py:571} INFO - 26/08/21 04:35:31 INFO TaskSetManager: Starting task 33.0 in stage 3.0 (TID 38) (172.18.0.6, executor 0, partition 33, PROCESS_LOCAL, 7619 bytes)
[2026-08-21T04:35:31.472+0000] {spark_submit.py:571} INFO - 26/08/21 04:35:31 INFO TaskSetManager: Finished task 25.0 in stage 3.0 (TID 31) in 460 ms on 172.18.0.6 (executor 0) (31/50)
[2026-08-21T04:35:31.589+0000] {spark_submit.py:571} INFO - 26/08/21 04:35:31 INFO BlockManagerInfo: Added rdd_14_31 in memory on 172.18.0.7:35755 (size: 46.0 B, free: 434.2 MiB)
[2026-08-21T04:35:31.601+0000] {spark_submit.py:571} INFO - 26/08/21 04:35:31 INFO TaskSetManager: Starting task 34.0 in stage 3.0 (TID 39) (172.18.0.7, executor 1, partition 34, PROCESS_LOCAL, 7619 bytes)
[2026-08-21T04:35:31.603+0000] {spark_submit.py:571} INFO - 26/08/21 04:35:31 INFO TaskSetManager: Finished task 31.0 in stage 3.0 (TID 36) in 154 ms on 172.18.0.7 (executor 1) (32/50)
[2026-08-21T04:35:31.626+0000] {spark_submit.py:571} INFO - 26/08/21 04:35:31 INFO BlockManagerInfo: Added rdd_14_32 in memory on 172.18.0.7:35755 (size: 46.0 B, free: 434.2 MiB)
[2026-08-21T04:35:31.644+0000] {spark_submit.py:571} INFO - 26/08/21 04:35:31 INFO TaskSetManager: Starting task 35.0 in stage 3.0 (TID 40) (172.18.0.7, executor 1, partition 35, PROCESS_LOCAL, 7619 bytes)
[2026-08-21T04:35:31.646+0000] {spark_submit.py:571} INFO - 26/08/21 04:35:31 INFO TaskSetManager: Finished task 32.0 in stage 3.0 (TID 37) in 184 ms on 172.18.0.7 (executor 1) (33/50)
[2026-08-21T04:35:31.732+0000] {spark_submit.py:571} INFO - 26/08/21 04:35:31 INFO BlockManagerInfo: Added rdd_14_35 in memory on 172.18.0.7:35755 (size: 46.0 B, free: 434.2 MiB)
[2026-08-21T04:35:31.746+0000] {spark_submit.py:571} INFO - 26/08/21 04:35:31 INFO TaskSetManager: Starting task 36.0 in stage 3.0 (TID 41) (172.18.0.7, executor 1, partition 36, PROCESS_LOCAL, 7619 bytes)
[2026-08-21T04:35:31.749+0000] {spark_submit.py:571} INFO - 26/08/21 04:35:31 INFO TaskSetManager: Finished task 35.0 in stage 3.0 (TID 40) in 105 ms on 172.18.0.7 (executor 1) (34/50)
[2026-08-21T04:35:31.751+0000] {spark_submit.py:571} INFO - 26/08/21 04:35:31 INFO BlockManagerInfo: Added rdd_14_29 in memory on 172.18.0.6:36781 (size: 46.0 B, free: 434.2 MiB)
[2026-08-21T04:35:31.753+0000] {spark_submit.py:571} INFO - 26/08/21 04:35:31 INFO BlockManagerInfo: Added rdd_14_34 in memory on 172.18.0.7:35755 (size: 46.0 B, free: 434.2 MiB)
[2026-08-21T04:35:31.786+0000] {spark_submit.py:571} INFO - 26/08/21 04:35:31 INFO TaskSetManager: Starting task 37.0 in stage 3.0 (TID 42) (172.18.0.6, executor 0, partition 37, PROCESS_LOCAL, 7619 bytes)
[2026-08-21T04:35:31.791+0000] {spark_submit.py:571} INFO - 26/08/21 04:35:31 INFO TaskSetManager: Finished task 29.0 in stage 3.0 (TID 35) in 373 ms on 172.18.0.6 (executor 0) (35/50)
[2026-08-21T04:35:31.792+0000] {spark_submit.py:571} INFO - 26/08/21 04:35:31 INFO TaskSetManager: Starting task 38.0 in stage 3.0 (TID 43) (172.18.0.7, executor 1, partition 38, PROCESS_LOCAL, 7619 bytes)
[2026-08-21T04:35:31.796+0000] {spark_submit.py:571} INFO - 26/08/21 04:35:31 INFO TaskSetManager: Finished task 34.0 in stage 3.0 (TID 39) in 196 ms on 172.18.0.7 (executor 1) (36/50)
[2026-08-21T04:35:31.830+0000] {spark_submit.py:571} INFO - 26/08/21 04:35:31 INFO BlockManagerInfo: Added rdd_14_33 in memory on 172.18.0.6:36781 (size: 46.0 B, free: 434.2 MiB)
[2026-08-21T04:35:31.876+0000] {spark_submit.py:571} INFO - 26/08/21 04:35:31 INFO TaskSetManager: Starting task 39.0 in stage 3.0 (TID 44) (172.18.0.6, executor 0, partition 39, PROCESS_LOCAL, 7619 bytes)
[2026-08-21T04:35:31.880+0000] {spark_submit.py:571} INFO - 26/08/21 04:35:31 INFO TaskSetManager: Finished task 33.0 in stage 3.0 (TID 38) in 408 ms on 172.18.0.6 (executor 0) (37/50)
[2026-08-21T04:35:31.913+0000] {spark_submit.py:571} INFO - 26/08/21 04:35:31 INFO BlockManagerInfo: Added rdd_14_38 in memory on 172.18.0.7:35755 (size: 46.0 B, free: 434.2 MiB)
[2026-08-21T04:35:31.934+0000] {spark_submit.py:571} INFO - 26/08/21 04:35:31 INFO TaskSetManager: Starting task 40.0 in stage 3.0 (TID 45) (172.18.0.7, executor 1, partition 40, PROCESS_LOCAL, 7619 bytes)
[2026-08-21T04:35:31.938+0000] {spark_submit.py:571} INFO - 26/08/21 04:35:31 INFO TaskSetManager: Finished task 38.0 in stage 3.0 (TID 43) in 141 ms on 172.18.0.7 (executor 1) (38/50)
[2026-08-21T04:35:31.940+0000] {spark_submit.py:571} INFO - 26/08/21 04:35:31 INFO BlockManagerInfo: Added rdd_14_36 in memory on 172.18.0.7:35755 (size: 46.0 B, free: 434.2 MiB)
[2026-08-21T04:35:31.958+0000] {spark_submit.py:571} INFO - 26/08/21 04:35:31 INFO TaskSetManager: Starting task 41.0 in stage 3.0 (TID 46) (172.18.0.7, executor 1, partition 41, PROCESS_LOCAL, 7619 bytes)
[2026-08-21T04:35:31.965+0000] {spark_submit.py:571} INFO - 26/08/21 04:35:31 INFO TaskSetManager: Finished task 36.0 in stage 3.0 (TID 41) in 214 ms on 172.18.0.7 (executor 1) (39/50)
[2026-08-21T04:35:31.991+0000] {spark_submit.py:571} INFO - 26/08/21 04:35:31 INFO BlockManagerInfo: Added rdd_14_37 in memory on 172.18.0.6:36781 (size: 46.0 B, free: 434.2 MiB)
[2026-08-21T04:35:32.004+0000] {spark_submit.py:571} INFO - 26/08/21 04:35:32 INFO TaskSetManager: Starting task 43.0 in stage 3.0 (TID 47) (172.18.0.6, executor 0, partition 43, PROCESS_LOCAL, 7619 bytes)
[2026-08-21T04:35:32.010+0000] {spark_submit.py:571} INFO - 26/08/21 04:35:32 INFO TaskSetManager: Finished task 37.0 in stage 3.0 (TID 42) in 225 ms on 172.18.0.6 (executor 0) (40/50)
[2026-08-21T04:35:32.060+0000] {spark_submit.py:571} INFO - 26/08/21 04:35:32 INFO BlockManagerInfo: Added rdd_14_39 in memory on 172.18.0.6:36781 (size: 46.0 B, free: 434.2 MiB)
[2026-08-21T04:35:32.078+0000] {spark_submit.py:571} INFO - 26/08/21 04:35:32 INFO TaskSetManager: Starting task 44.0 in stage 3.0 (TID 48) (172.18.0.6, executor 0, partition 44, PROCESS_LOCAL, 7619 bytes)
[2026-08-21T04:35:32.082+0000] {spark_submit.py:571} INFO - 26/08/21 04:35:32 INFO TaskSetManager: Finished task 39.0 in stage 3.0 (TID 44) in 208 ms on 172.18.0.6 (executor 0) (41/50)
[2026-08-21T04:35:32.124+0000] {spark_submit.py:571} INFO - 26/08/21 04:35:32 INFO BlockManagerInfo: Added rdd_14_40 in memory on 172.18.0.7:35755 (size: 46.0 B, free: 434.2 MiB)
[2026-08-21T04:35:32.125+0000] {spark_submit.py:571} INFO - 26/08/21 04:35:32 INFO BlockManagerInfo: Added rdd_14_41 in memory on 172.18.0.7:35755 (size: 46.0 B, free: 434.2 MiB)
[2026-08-21T04:35:32.147+0000] {spark_submit.py:571} INFO - 26/08/21 04:35:32 INFO TaskSetManager: Starting task 45.0 in stage 3.0 (TID 49) (172.18.0.7, executor 1, partition 45, PROCESS_LOCAL, 7619 bytes)
[2026-08-21T04:35:32.148+0000] {spark_submit.py:571} INFO - 26/08/21 04:35:32 INFO TaskSetManager: Starting task 46.0 in stage 3.0 (TID 50) (172.18.0.7, executor 1, partition 46, PROCESS_LOCAL, 7619 bytes)
[2026-08-21T04:35:32.149+0000] {spark_submit.py:571} INFO - 26/08/21 04:35:32 INFO TaskSetManager: Finished task 41.0 in stage 3.0 (TID 46) in 193 ms on 172.18.0.7 (executor 1) (42/50)
[2026-08-21T04:35:32.151+0000] {spark_submit.py:571} INFO - 26/08/21 04:35:32 INFO TaskSetManager: Finished task 40.0 in stage 3.0 (TID 45) in 216 ms on 172.18.0.7 (executor 1) (43/50)
[2026-08-21T04:35:32.233+0000] {spark_submit.py:571} INFO - 26/08/21 04:35:32 INFO BlockManagerInfo: Added rdd_14_43 in memory on 172.18.0.6:36781 (size: 46.0 B, free: 434.2 MiB)
[2026-08-21T04:35:32.258+0000] {spark_submit.py:571} INFO - 26/08/21 04:35:32 INFO TaskSetManager: Starting task 47.0 in stage 3.0 (TID 51) (172.18.0.6, executor 0, partition 47, PROCESS_LOCAL, 7619 bytes)
[2026-08-21T04:35:32.262+0000] {spark_submit.py:571} INFO - 26/08/21 04:35:32 INFO TaskSetManager: Finished task 43.0 in stage 3.0 (TID 47) in 258 ms on 172.18.0.6 (executor 0) (44/50)
[2026-08-21T04:35:32.324+0000] {spark_submit.py:571} INFO - 26/08/21 04:35:32 INFO BlockManagerInfo: Added rdd_14_44 in memory on 172.18.0.6:36781 (size: 46.0 B, free: 434.2 MiB)
[2026-08-21T04:35:32.350+0000] {spark_submit.py:571} INFO - 26/08/21 04:35:32 INFO BlockManagerInfo: Added rdd_14_45 in memory on 172.18.0.7:35755 (size: 46.0 B, free: 434.2 MiB)
[2026-08-21T04:35:32.359+0000] {spark_submit.py:571} INFO - 26/08/21 04:35:32 INFO TaskSetManager: Starting task 48.0 in stage 3.0 (TID 52) (172.18.0.7, executor 1, partition 48, PROCESS_LOCAL, 7619 bytes)
[2026-08-21T04:35:32.364+0000] {spark_submit.py:571} INFO - 26/08/21 04:35:32 INFO TaskSetManager: Finished task 45.0 in stage 3.0 (TID 49) in 219 ms on 172.18.0.7 (executor 1) (45/50)
[2026-08-21T04:35:32.372+0000] {spark_submit.py:571} INFO - 26/08/21 04:35:32 INFO BlockManagerInfo: Added rdd_14_46 in memory on 172.18.0.7:35755 (size: 46.0 B, free: 434.2 MiB)
[2026-08-21T04:35:32.380+0000] {spark_submit.py:571} INFO - 26/08/21 04:35:32 INFO TaskSetManager: Starting task 49.0 in stage 3.0 (TID 53) (172.18.0.7, executor 1, partition 49, PROCESS_LOCAL, 7619 bytes)
[2026-08-21T04:35:32.381+0000] {spark_submit.py:571} INFO - 26/08/21 04:35:32 INFO TaskSetManager: Finished task 46.0 in stage 3.0 (TID 50) in 234 ms on 172.18.0.7 (executor 1) (46/50)
[2026-08-21T04:35:32.390+0000] {spark_submit.py:571} INFO - 26/08/21 04:35:32 INFO TaskSetManager: Finished task 44.0 in stage 3.0 (TID 48) in 310 ms on 172.18.0.6 (executor 0) (47/50)
[2026-08-21T04:35:32.446+0000] {spark_submit.py:571} INFO - 26/08/21 04:35:32 INFO BlockManagerInfo: Added rdd_14_47 in memory on 172.18.0.6:36781 (size: 46.0 B, free: 434.2 MiB)
[2026-08-21T04:35:32.467+0000] {spark_submit.py:571} INFO - 26/08/21 04:35:32 INFO BlockManagerInfo: Added rdd_14_49 in memory on 172.18.0.7:35755 (size: 46.0 B, free: 434.2 MiB)
[2026-08-21T04:35:32.470+0000] {spark_submit.py:571} INFO - 26/08/21 04:35:32 INFO TaskSetManager: Finished task 47.0 in stage 3.0 (TID 51) in 208 ms on 172.18.0.6 (executor 0) (48/50)
[2026-08-21T04:35:32.485+0000] {spark_submit.py:571} INFO - 26/08/21 04:35:32 INFO TaskSetManager: Finished task 49.0 in stage 3.0 (TID 53) in 106 ms on 172.18.0.7 (executor 1) (49/50)
[2026-08-21T04:35:32.497+0000] {spark_submit.py:571} INFO - 26/08/21 04:35:32 INFO BlockManagerInfo: Added rdd_14_48 in memory on 172.18.0.7:35755 (size: 46.0 B, free: 434.2 MiB)
[2026-08-21T04:35:32.512+0000] {spark_submit.py:571} INFO - 26/08/21 04:35:32 INFO TaskSetManager: Finished task 48.0 in stage 3.0 (TID 52) in 153 ms on 172.18.0.7 (executor 1) (50/50)
[2026-08-21T04:35:32.514+0000] {spark_submit.py:571} INFO - 26/08/21 04:35:32 INFO TaskSchedulerImpl: Removed TaskSet 3.0, whose tasks have all completed, from pool
[2026-08-21T04:35:32.516+0000] {spark_submit.py:571} INFO - 26/08/21 04:35:32 INFO DAGScheduler: ResultStage 3 ($anonfun$recordDeltaOperationInternal$1 at DatabricksLogging.scala:128) finished in 8.022 s
[2026-08-21T04:35:32.516+0000] {spark_submit.py:571} INFO - 26/08/21 04:35:32 INFO DAGScheduler: Job 2 is finished. Cancelling potential speculative or zombie tasks for this job
[2026-08-21T04:35:32.520+0000] {spark_submit.py:571} INFO - 26/08/21 04:35:32 INFO TaskSchedulerImpl: Killing all running tasks in stage 3: Stage finished
[2026-08-21T04:35:32.520+0000] {spark_submit.py:571} INFO - 26/08/21 04:35:32 INFO DAGScheduler: Job 2 finished: $anonfun$recordDeltaOperationInternal$1 at DatabricksLogging.scala:128, took 8.059944 s
[2026-08-21T04:35:32.555+0000] {spark_submit.py:571} INFO - 26/08/21 04:35:32 INFO CodeGenerator: Code generated in 20.809591 ms
[2026-08-21T04:35:32.560+0000] {spark_submit.py:571} INFO - 26/08/21 04:35:32 INFO Snapshot: [tableId=553802dd-42b6-4cf1-8af2-e0916230ea16] DELTA: Compute snapshot for version: 1
[2026-08-21T04:35:32.846+0000] {spark_submit.py:571} INFO - 26/08/21 04:35:32 INFO CodeGenerator: Code generated in 61.103004 ms
[2026-08-21T04:35:32.888+0000] {spark_submit.py:571} INFO - 26/08/21 04:35:32 INFO BlockManagerInfo: Removed broadcast_5_piece0 on c90a551abb73:39895 in memory (size: 155.9 KiB, free: 434.3 MiB)
[2026-08-21T04:35:32.889+0000] {spark_submit.py:571} INFO - 26/08/21 04:35:32 INFO BlockManagerInfo: Removed broadcast_5_piece0 on 172.18.0.6:36781 in memory (size: 155.9 KiB, free: 434.4 MiB)
[2026-08-21T04:35:32.895+0000] {spark_submit.py:571} INFO - 26/08/21 04:35:32 INFO BlockManagerInfo: Removed broadcast_5_piece0 on 172.18.0.7:35755 in memory (size: 155.9 KiB, free: 434.4 MiB)
[2026-08-21T04:35:32.898+0000] {spark_submit.py:571} INFO - 26/08/21 04:35:32 INFO DAGScheduler: Registering RDD 19 ($anonfun$recordDeltaOperationInternal$1 at DatabricksLogging.scala:128) as input to shuffle 1
[2026-08-21T04:35:32.902+0000] {spark_submit.py:571} INFO - 26/08/21 04:35:32 INFO DAGScheduler: Got map stage job 3 ($anonfun$recordDeltaOperationInternal$1 at DatabricksLogging.scala:128) with 50 output partitions
[2026-08-21T04:35:32.903+0000] {spark_submit.py:571} INFO - 26/08/21 04:35:32 INFO DAGScheduler: Final stage: ShuffleMapStage 5 ($anonfun$recordDeltaOperationInternal$1 at DatabricksLogging.scala:128)
[2026-08-21T04:35:32.903+0000] {spark_submit.py:571} INFO - 26/08/21 04:35:32 INFO DAGScheduler: Parents of final stage: List(ShuffleMapStage 4)
[2026-08-21T04:35:32.905+0000] {spark_submit.py:571} INFO - 26/08/21 04:35:32 INFO DAGScheduler: Missing parents: List()
[2026-08-21T04:35:32.905+0000] {spark_submit.py:571} INFO - 26/08/21 04:35:32 INFO DAGScheduler: Submitting ShuffleMapStage 5 (MapPartitionsRDD[19] at $anonfun$recordDeltaOperationInternal$1 at DatabricksLogging.scala:128), which has no missing parents
[2026-08-21T04:35:32.923+0000] {spark_submit.py:571} INFO - 26/08/21 04:35:32 INFO MemoryStore: Block broadcast_6 stored as values in memory (estimated size 602.3 KiB, free 433.4 MiB)
[2026-08-21T04:35:32.925+0000] {spark_submit.py:571} INFO - 26/08/21 04:35:32 INFO MemoryStore: Block broadcast_6_piece0 stored as bytes in memory (estimated size 137.9 KiB, free 433.2 MiB)
[2026-08-21T04:35:32.926+0000] {spark_submit.py:571} INFO - 26/08/21 04:35:32 INFO BlockManagerInfo: Added broadcast_6_piece0 in memory on c90a551abb73:39895 (size: 137.9 KiB, free: 434.2 MiB)
[2026-08-21T04:35:32.926+0000] {spark_submit.py:571} INFO - 26/08/21 04:35:32 INFO SparkContext: Created broadcast 6 from broadcast at DAGScheduler.scala:1585
[2026-08-21T04:35:32.927+0000] {spark_submit.py:571} INFO - 26/08/21 04:35:32 INFO DAGScheduler: Submitting 50 missing tasks from ShuffleMapStage 5 (MapPartitionsRDD[19] at $anonfun$recordDeltaOperationInternal$1 at DatabricksLogging.scala:128) (first 15 tasks are for partitions Vector(0, 1, 2, 3, 4, 5, 6, 7, 8, 9, 10, 11, 12, 13, 14))
[2026-08-21T04:35:32.927+0000] {spark_submit.py:571} INFO - 26/08/21 04:35:32 INFO TaskSchedulerImpl: Adding task set 5.0 with 50 tasks resource profile 0
[2026-08-21T04:35:32.929+0000] {spark_submit.py:571} INFO - 26/08/21 04:35:32 INFO TaskSetManager: Starting task 2.0 in stage 5.0 (TID 54) (172.18.0.7, executor 1, partition 2, PROCESS_LOCAL, 7608 bytes)
[2026-08-21T04:35:32.930+0000] {spark_submit.py:571} INFO - 26/08/21 04:35:32 INFO TaskSetManager: Starting task 0.0 in stage 5.0 (TID 55) (172.18.0.6, executor 0, partition 0, PROCESS_LOCAL, 7608 bytes)
[2026-08-21T04:35:32.930+0000] {spark_submit.py:571} INFO - 26/08/21 04:35:32 INFO TaskSetManager: Starting task 3.0 in stage 5.0 (TID 56) (172.18.0.7, executor 1, partition 3, PROCESS_LOCAL, 7608 bytes)
[2026-08-21T04:35:32.930+0000] {spark_submit.py:571} INFO - 26/08/21 04:35:32 INFO TaskSetManager: Starting task 1.0 in stage 5.0 (TID 57) (172.18.0.6, executor 0, partition 1, PROCESS_LOCAL, 7608 bytes)
[2026-08-21T04:35:32.955+0000] {spark_submit.py:571} INFO - 26/08/21 04:35:32 INFO BlockManagerInfo: Added broadcast_6_piece0 in memory on 172.18.0.7:35755 (size: 137.9 KiB, free: 434.2 MiB)
[2026-08-21T04:35:32.960+0000] {spark_submit.py:571} INFO - 26/08/21 04:35:32 INFO BlockManagerInfo: Added broadcast_6_piece0 in memory on 172.18.0.6:36781 (size: 137.9 KiB, free: 434.2 MiB)
[2026-08-21T04:35:34.067+0000] {spark_submit.py:571} INFO - 26/08/21 04:35:34 INFO TaskSetManager: Starting task 4.0 in stage 5.0 (TID 58) (172.18.0.6, executor 0, partition 4, PROCESS_LOCAL, 7608 bytes)
[2026-08-21T04:35:34.068+0000] {spark_submit.py:571} INFO - 26/08/21 04:35:34 INFO TaskSetManager: Finished task 0.0 in stage 5.0 (TID 55) in 1138 ms on 172.18.0.6 (executor 0) (1/50)
[2026-08-21T04:35:34.079+0000] {spark_submit.py:571} INFO - 26/08/21 04:35:34 INFO TaskSetManager: Starting task 7.0 in stage 5.0 (TID 59) (172.18.0.6, executor 0, partition 7, PROCESS_LOCAL, 7608 bytes)
[2026-08-21T04:35:34.081+0000] {spark_submit.py:571} INFO - 26/08/21 04:35:34 INFO TaskSetManager: Finished task 1.0 in stage 5.0 (TID 57) in 1147 ms on 172.18.0.6 (executor 0) (2/50)
[2026-08-21T04:35:34.178+0000] {spark_submit.py:571} INFO - 26/08/21 04:35:34 INFO TaskSetManager: Starting task 10.0 in stage 5.0 (TID 60) (172.18.0.6, executor 0, partition 10, PROCESS_LOCAL, 7608 bytes)
[2026-08-21T04:35:34.180+0000] {spark_submit.py:571} INFO - 26/08/21 04:35:34 INFO TaskSetManager: Finished task 4.0 in stage 5.0 (TID 58) in 113 ms on 172.18.0.6 (executor 0) (3/50)
[2026-08-21T04:35:34.210+0000] {spark_submit.py:571} INFO - 26/08/21 04:35:34 INFO TaskSetManager: Starting task 11.0 in stage 5.0 (TID 61) (172.18.0.6, executor 0, partition 11, PROCESS_LOCAL, 7608 bytes)
[2026-08-21T04:35:34.212+0000] {spark_submit.py:571} INFO - 26/08/21 04:35:34 INFO TaskSetManager: Finished task 7.0 in stage 5.0 (TID 59) in 135 ms on 172.18.0.6 (executor 0) (4/50)
[2026-08-21T04:35:34.265+0000] {spark_submit.py:571} INFO - 26/08/21 04:35:34 INFO TaskSetManager: Starting task 12.0 in stage 5.0 (TID 62) (172.18.0.6, executor 0, partition 12, PROCESS_LOCAL, 7608 bytes)
[2026-08-21T04:35:34.267+0000] {spark_submit.py:571} INFO - 26/08/21 04:35:34 INFO TaskSetManager: Finished task 10.0 in stage 5.0 (TID 60) in 88 ms on 172.18.0.6 (executor 0) (5/50)
[2026-08-21T04:35:34.293+0000] {spark_submit.py:571} INFO - 26/08/21 04:35:34 INFO TaskSetManager: Starting task 15.0 in stage 5.0 (TID 63) (172.18.0.6, executor 0, partition 15, PROCESS_LOCAL, 7608 bytes)
[2026-08-21T04:35:34.296+0000] {spark_submit.py:571} INFO - 26/08/21 04:35:34 INFO TaskSetManager: Finished task 11.0 in stage 5.0 (TID 61) in 85 ms on 172.18.0.6 (executor 0) (6/50)
[2026-08-21T04:35:34.336+0000] {spark_submit.py:571} INFO - 26/08/21 04:35:34 INFO TaskSetManager: Starting task 16.0 in stage 5.0 (TID 64) (172.18.0.6, executor 0, partition 16, PROCESS_LOCAL, 7608 bytes)
[2026-08-21T04:35:34.339+0000] {spark_submit.py:571} INFO - 26/08/21 04:35:34 INFO TaskSetManager: Starting task 5.0 in stage 5.0 (TID 65) (172.18.0.7, executor 1, partition 5, PROCESS_LOCAL, 7608 bytes)
[2026-08-21T04:35:34.342+0000] {spark_submit.py:571} INFO - 26/08/21 04:35:34 INFO TaskSetManager: Starting task 6.0 in stage 5.0 (TID 66) (172.18.0.7, executor 1, partition 6, PROCESS_LOCAL, 7608 bytes)
[2026-08-21T04:35:34.342+0000] {spark_submit.py:571} INFO - 26/08/21 04:35:34 INFO TaskSetManager: Finished task 12.0 in stage 5.0 (TID 62) in 75 ms on 172.18.0.6 (executor 0) (7/50)
[2026-08-21T04:35:34.344+0000] {spark_submit.py:571} INFO - 26/08/21 04:35:34 INFO TaskSetManager: Finished task 3.0 in stage 5.0 (TID 56) in 1411 ms on 172.18.0.7 (executor 1) (8/50)
[2026-08-21T04:35:34.344+0000] {spark_submit.py:571} INFO - 26/08/21 04:35:34 INFO TaskSetManager: Finished task 2.0 in stage 5.0 (TID 54) in 1411 ms on 172.18.0.7 (executor 1) (9/50)
[2026-08-21T04:35:34.375+0000] {spark_submit.py:571} INFO - 26/08/21 04:35:34 INFO TaskSetManager: Starting task 19.0 in stage 5.0 (TID 67) (172.18.0.6, executor 0, partition 19, PROCESS_LOCAL, 7608 bytes)
[2026-08-21T04:35:34.377+0000] {spark_submit.py:571} INFO - 26/08/21 04:35:34 INFO TaskSetManager: Finished task 15.0 in stage 5.0 (TID 63) in 85 ms on 172.18.0.6 (executor 0) (10/50)
[2026-08-21T04:35:34.408+0000] {spark_submit.py:571} INFO - 26/08/21 04:35:34 INFO TaskSetManager: Starting task 20.0 in stage 5.0 (TID 68) (172.18.0.6, executor 0, partition 20, PROCESS_LOCAL, 7608 bytes)
[2026-08-21T04:35:34.408+0000] {spark_submit.py:571} INFO - 26/08/21 04:35:34 INFO TaskSetManager: Finished task 16.0 in stage 5.0 (TID 64) in 75 ms on 172.18.0.6 (executor 0) (11/50)
[2026-08-21T04:35:34.420+0000] {spark_submit.py:571} INFO - 26/08/21 04:35:34 INFO TaskSetManager: Starting task 8.0 in stage 5.0 (TID 69) (172.18.0.7, executor 1, partition 8, PROCESS_LOCAL, 7608 bytes)
[2026-08-21T04:35:34.421+0000] {spark_submit.py:571} INFO - 26/08/21 04:35:34 INFO TaskSetManager: Finished task 5.0 in stage 5.0 (TID 65) in 84 ms on 172.18.0.7 (executor 1) (12/50)
[2026-08-21T04:35:34.450+0000] {spark_submit.py:571} INFO - 26/08/21 04:35:34 INFO TaskSetManager: Starting task 9.0 in stage 5.0 (TID 70) (172.18.0.7, executor 1, partition 9, PROCESS_LOCAL, 7608 bytes)
[2026-08-21T04:35:34.451+0000] {spark_submit.py:571} INFO - 26/08/21 04:35:34 INFO TaskSetManager: Finished task 6.0 in stage 5.0 (TID 66) in 112 ms on 172.18.0.7 (executor 1) (13/50)
[2026-08-21T04:35:34.470+0000] {spark_submit.py:571} INFO - 26/08/21 04:35:34 INFO TaskSetManager: Starting task 23.0 in stage 5.0 (TID 71) (172.18.0.6, executor 0, partition 23, PROCESS_LOCAL, 7608 bytes)
[2026-08-21T04:35:34.472+0000] {spark_submit.py:571} INFO - 26/08/21 04:35:34 INFO TaskSetManager: Finished task 19.0 in stage 5.0 (TID 67) in 98 ms on 172.18.0.6 (executor 0) (14/50)
[2026-08-21T04:35:34.476+0000] {spark_submit.py:571} INFO - 26/08/21 04:35:34 INFO TaskSetManager: Starting task 25.0 in stage 5.0 (TID 72) (172.18.0.6, executor 0, partition 25, PROCESS_LOCAL, 7608 bytes)
[2026-08-21T04:35:34.478+0000] {spark_submit.py:571} INFO - 26/08/21 04:35:34 INFO TaskSetManager: Finished task 20.0 in stage 5.0 (TID 68) in 69 ms on 172.18.0.6 (executor 0) (15/50)
[2026-08-21T04:35:34.579+0000] {spark_submit.py:571} INFO - 26/08/21 04:35:34 INFO TaskSetManager: Starting task 13.0 in stage 5.0 (TID 73) (172.18.0.7, executor 1, partition 13, PROCESS_LOCAL, 7608 bytes)
[2026-08-21T04:35:34.581+0000] {spark_submit.py:571} INFO - 26/08/21 04:35:34 INFO TaskSetManager: Starting task 14.0 in stage 5.0 (TID 74) (172.18.0.7, executor 1, partition 14, PROCESS_LOCAL, 7608 bytes)
[2026-08-21T04:35:34.583+0000] {spark_submit.py:571} INFO - 26/08/21 04:35:34 INFO TaskSetManager: Finished task 9.0 in stage 5.0 (TID 70) in 130 ms on 172.18.0.7 (executor 1) (16/50)
[2026-08-21T04:35:34.584+0000] {spark_submit.py:571} INFO - 26/08/21 04:35:34 INFO TaskSetManager: Finished task 8.0 in stage 5.0 (TID 69) in 159 ms on 172.18.0.7 (executor 1) (17/50)
[2026-08-21T04:35:34.596+0000] {spark_submit.py:571} INFO - 26/08/21 04:35:34 INFO TaskSetManager: Starting task 28.0 in stage 5.0 (TID 75) (172.18.0.6, executor 0, partition 28, PROCESS_LOCAL, 7608 bytes)
[2026-08-21T04:35:34.599+0000] {spark_submit.py:571} INFO - 26/08/21 04:35:34 INFO TaskSetManager: Finished task 23.0 in stage 5.0 (TID 71) in 128 ms on 172.18.0.6 (executor 0) (18/50)
[2026-08-21T04:35:34.627+0000] {spark_submit.py:571} INFO - 26/08/21 04:35:34 INFO TaskSetManager: Starting task 29.0 in stage 5.0 (TID 76) (172.18.0.6, executor 0, partition 29, PROCESS_LOCAL, 7608 bytes)
[2026-08-21T04:35:34.629+0000] {spark_submit.py:571} INFO - 26/08/21 04:35:34 INFO TaskSetManager: Finished task 25.0 in stage 5.0 (TID 72) in 153 ms on 172.18.0.6 (executor 0) (19/50)
[2026-08-21T04:35:34.662+0000] {spark_submit.py:571} INFO - 26/08/21 04:35:34 INFO TaskSetManager: Starting task 17.0 in stage 5.0 (TID 77) (172.18.0.7, executor 1, partition 17, PROCESS_LOCAL, 7608 bytes)
[2026-08-21T04:35:34.665+0000] {spark_submit.py:571} INFO - 26/08/21 04:35:34 INFO TaskSetManager: Finished task 13.0 in stage 5.0 (TID 73) in 89 ms on 172.18.0.7 (executor 1) (20/50)
[2026-08-21T04:35:34.666+0000] {spark_submit.py:571} INFO - 26/08/21 04:35:34 INFO TaskSetManager: Starting task 18.0 in stage 5.0 (TID 78) (172.18.0.7, executor 1, partition 18, PROCESS_LOCAL, 7608 bytes)
[2026-08-21T04:35:34.667+0000] {spark_submit.py:571} INFO - 26/08/21 04:35:34 INFO TaskSetManager: Finished task 14.0 in stage 5.0 (TID 74) in 89 ms on 172.18.0.7 (executor 1) (21/50)
[2026-08-21T04:35:34.738+0000] {spark_submit.py:571} INFO - 26/08/21 04:35:34 INFO TaskSetManager: Starting task 33.0 in stage 5.0 (TID 79) (172.18.0.6, executor 0, partition 33, PROCESS_LOCAL, 7608 bytes)
[2026-08-21T04:35:34.742+0000] {spark_submit.py:571} INFO - 26/08/21 04:35:34 INFO TaskSetManager: Finished task 28.0 in stage 5.0 (TID 75) in 146 ms on 172.18.0.6 (executor 0) (22/50)
[2026-08-21T04:35:34.767+0000] {spark_submit.py:571} INFO - 26/08/21 04:35:34 INFO TaskSetManager: Starting task 21.0 in stage 5.0 (TID 80) (172.18.0.7, executor 1, partition 21, PROCESS_LOCAL, 7608 bytes)
[2026-08-21T04:35:34.771+0000] {spark_submit.py:571} INFO - 26/08/21 04:35:34 INFO TaskSetManager: Starting task 22.0 in stage 5.0 (TID 81) (172.18.0.7, executor 1, partition 22, PROCESS_LOCAL, 7608 bytes)
[2026-08-21T04:35:34.772+0000] {spark_submit.py:571} INFO - 26/08/21 04:35:34 INFO TaskSetManager: Finished task 17.0 in stage 5.0 (TID 77) in 110 ms on 172.18.0.7 (executor 1) (23/50)
[2026-08-21T04:35:34.777+0000] {spark_submit.py:571} INFO - 26/08/21 04:35:34 INFO TaskSetManager: Starting task 37.0 in stage 5.0 (TID 82) (172.18.0.6, executor 0, partition 37, PROCESS_LOCAL, 7608 bytes)
[2026-08-21T04:35:34.778+0000] {spark_submit.py:571} INFO - 26/08/21 04:35:34 INFO TaskSetManager: Finished task 29.0 in stage 5.0 (TID 76) in 153 ms on 172.18.0.6 (executor 0) (24/50)
[2026-08-21T04:35:34.780+0000] {spark_submit.py:571} INFO - 26/08/21 04:35:34 INFO TaskSetManager: Finished task 18.0 in stage 5.0 (TID 78) in 113 ms on 172.18.0.7 (executor 1) (25/50)
[2026-08-21T04:35:34.849+0000] {spark_submit.py:571} INFO - 26/08/21 04:35:34 INFO TaskSetManager: Starting task 39.0 in stage 5.0 (TID 83) (172.18.0.6, executor 0, partition 39, PROCESS_LOCAL, 7608 bytes)
[2026-08-21T04:35:34.851+0000] {spark_submit.py:571} INFO - 26/08/21 04:35:34 INFO TaskSetManager: Finished task 33.0 in stage 5.0 (TID 79) in 114 ms on 172.18.0.6 (executor 0) (26/50)
[2026-08-21T04:35:34.865+0000] {spark_submit.py:571} INFO - 26/08/21 04:35:34 INFO TaskSetManager: Starting task 24.0 in stage 5.0 (TID 84) (172.18.0.7, executor 1, partition 24, PROCESS_LOCAL, 7608 bytes)
[2026-08-21T04:35:34.866+0000] {spark_submit.py:571} INFO - 26/08/21 04:35:34 INFO TaskSetManager: Starting task 26.0 in stage 5.0 (TID 85) (172.18.0.7, executor 1, partition 26, PROCESS_LOCAL, 7608 bytes)
[2026-08-21T04:35:34.869+0000] {spark_submit.py:571} INFO - 26/08/21 04:35:34 INFO TaskSetManager: Finished task 21.0 in stage 5.0 (TID 80) in 102 ms on 172.18.0.7 (executor 1) (27/50)
[2026-08-21T04:35:34.869+0000] {spark_submit.py:571} INFO - 26/08/21 04:35:34 INFO TaskSetManager: Finished task 22.0 in stage 5.0 (TID 81) in 100 ms on 172.18.0.7 (executor 1) (28/50)
[2026-08-21T04:35:34.877+0000] {spark_submit.py:571} INFO - 26/08/21 04:35:34 INFO TaskSetManager: Starting task 42.0 in stage 5.0 (TID 86) (172.18.0.6, executor 0, partition 42, PROCESS_LOCAL, 7608 bytes)
[2026-08-21T04:35:34.878+0000] {spark_submit.py:571} INFO - 26/08/21 04:35:34 INFO TaskSetManager: Finished task 37.0 in stage 5.0 (TID 82) in 101 ms on 172.18.0.6 (executor 0) (29/50)
[2026-08-21T04:35:34.904+0000] {spark_submit.py:571} INFO - 26/08/21 04:35:34 INFO TaskSetManager: Starting task 43.0 in stage 5.0 (TID 87) (172.18.0.6, executor 0, partition 43, PROCESS_LOCAL, 7608 bytes)
[2026-08-21T04:35:34.908+0000] {spark_submit.py:571} INFO - 26/08/21 04:35:34 INFO TaskSetManager: Finished task 39.0 in stage 5.0 (TID 83) in 56 ms on 172.18.0.6 (executor 0) (30/50)
[2026-08-21T04:35:34.926+0000] {spark_submit.py:571} INFO - 26/08/21 04:35:34 INFO TaskSetManager: Starting task 44.0 in stage 5.0 (TID 88) (172.18.0.6, executor 0, partition 44, PROCESS_LOCAL, 7608 bytes)
[2026-08-21T04:35:34.927+0000] {spark_submit.py:571} INFO - 26/08/21 04:35:34 INFO TaskSetManager: Finished task 42.0 in stage 5.0 (TID 86) in 52 ms on 172.18.0.6 (executor 0) (31/50)
[2026-08-21T04:35:34.956+0000] {spark_submit.py:571} INFO - 26/08/21 04:35:34 INFO TaskSetManager: Starting task 27.0 in stage 5.0 (TID 89) (172.18.0.7, executor 1, partition 27, PROCESS_LOCAL, 7608 bytes)
[2026-08-21T04:35:34.958+0000] {spark_submit.py:571} INFO - 26/08/21 04:35:34 INFO TaskSetManager: Finished task 26.0 in stage 5.0 (TID 85) in 90 ms on 172.18.0.7 (executor 1) (32/50)
[2026-08-21T04:35:34.963+0000] {spark_submit.py:571} INFO - 26/08/21 04:35:34 INFO TaskSetManager: Starting task 30.0 in stage 5.0 (TID 90) (172.18.0.7, executor 1, partition 30, PROCESS_LOCAL, 7608 bytes)
[2026-08-21T04:35:34.968+0000] {spark_submit.py:571} INFO - 26/08/21 04:35:34 INFO TaskSetManager: Finished task 24.0 in stage 5.0 (TID 84) in 105 ms on 172.18.0.7 (executor 1) (33/50)
[2026-08-21T04:35:34.970+0000] {spark_submit.py:571} INFO - 26/08/21 04:35:34 INFO TaskSetManager: Starting task 47.0 in stage 5.0 (TID 91) (172.18.0.6, executor 0, partition 47, PROCESS_LOCAL, 7608 bytes)
[2026-08-21T04:35:34.971+0000] {spark_submit.py:571} INFO - 26/08/21 04:35:34 INFO TaskSetManager: Finished task 43.0 in stage 5.0 (TID 87) in 68 ms on 172.18.0.6 (executor 0) (34/50)
[2026-08-21T04:35:34.985+0000] {spark_submit.py:571} INFO - 26/08/21 04:35:34 INFO TaskSetManager: Finished task 44.0 in stage 5.0 (TID 88) in 60 ms on 172.18.0.6 (executor 0) (35/50)
[2026-08-21T04:35:35.014+0000] {spark_submit.py:571} INFO - 26/08/21 04:35:35 INFO TaskSetManager: Starting task 31.0 in stage 5.0 (TID 92) (172.18.0.7, executor 1, partition 31, PROCESS_LOCAL, 7608 bytes)
[2026-08-21T04:35:35.019+0000] {spark_submit.py:571} INFO - 26/08/21 04:35:35 INFO TaskSetManager: Finished task 27.0 in stage 5.0 (TID 89) in 64 ms on 172.18.0.7 (executor 1) (36/50)
[2026-08-21T04:35:35.035+0000] {spark_submit.py:571} INFO - 26/08/21 04:35:35 INFO TaskSetManager: Finished task 47.0 in stage 5.0 (TID 91) in 66 ms on 172.18.0.6 (executor 0) (37/50)
[2026-08-21T04:35:35.044+0000] {spark_submit.py:571} INFO - 26/08/21 04:35:35 INFO TaskSetManager: Starting task 32.0 in stage 5.0 (TID 93) (172.18.0.7, executor 1, partition 32, PROCESS_LOCAL, 7608 bytes)
[2026-08-21T04:35:35.046+0000] {spark_submit.py:571} INFO - 26/08/21 04:35:35 INFO TaskSetManager: Finished task 30.0 in stage 5.0 (TID 90) in 83 ms on 172.18.0.7 (executor 1) (38/50)
[2026-08-21T04:35:35.066+0000] {spark_submit.py:571} INFO - 26/08/21 04:35:35 INFO TaskSetManager: Starting task 34.0 in stage 5.0 (TID 94) (172.18.0.7, executor 1, partition 34, PROCESS_LOCAL, 7608 bytes)
[2026-08-21T04:35:35.067+0000] {spark_submit.py:571} INFO - 26/08/21 04:35:35 INFO TaskSetManager: Finished task 31.0 in stage 5.0 (TID 92) in 54 ms on 172.18.0.7 (executor 1) (39/50)
[2026-08-21T04:35:35.091+0000] {spark_submit.py:571} INFO - 26/08/21 04:35:35 INFO TaskSetManager: Starting task 35.0 in stage 5.0 (TID 95) (172.18.0.7, executor 1, partition 35, PROCESS_LOCAL, 7608 bytes)
[2026-08-21T04:35:35.104+0000] {spark_submit.py:571} INFO - 26/08/21 04:35:35 INFO TaskSetManager: Finished task 32.0 in stage 5.0 (TID 93) in 62 ms on 172.18.0.7 (executor 1) (40/50)
[2026-08-21T04:35:35.123+0000] {spark_submit.py:571} INFO - 26/08/21 04:35:35 INFO TaskSetManager: Starting task 36.0 in stage 5.0 (TID 96) (172.18.0.7, executor 1, partition 36, PROCESS_LOCAL, 7608 bytes)
[2026-08-21T04:35:35.129+0000] {spark_submit.py:571} INFO - 26/08/21 04:35:35 INFO TaskSetManager: Finished task 34.0 in stage 5.0 (TID 94) in 59 ms on 172.18.0.7 (executor 1) (41/50)
[2026-08-21T04:35:35.160+0000] {spark_submit.py:571} INFO - 26/08/21 04:35:35 INFO TaskSetManager: Starting task 38.0 in stage 5.0 (TID 97) (172.18.0.7, executor 1, partition 38, PROCESS_LOCAL, 7608 bytes)
[2026-08-21T04:35:35.162+0000] {spark_submit.py:571} INFO - 26/08/21 04:35:35 INFO TaskSetManager: Finished task 35.0 in stage 5.0 (TID 95) in 72 ms on 172.18.0.7 (executor 1) (42/50)
[2026-08-21T04:35:35.181+0000] {spark_submit.py:571} INFO - 26/08/21 04:35:35 INFO TaskSetManager: Starting task 40.0 in stage 5.0 (TID 98) (172.18.0.7, executor 1, partition 40, PROCESS_LOCAL, 7608 bytes)
[2026-08-21T04:35:35.182+0000] {spark_submit.py:571} INFO - 26/08/21 04:35:35 INFO TaskSetManager: Finished task 36.0 in stage 5.0 (TID 96) in 58 ms on 172.18.0.7 (executor 1) (43/50)
[2026-08-21T04:35:35.248+0000] {spark_submit.py:571} INFO - 26/08/21 04:35:35 INFO TaskSetManager: Starting task 41.0 in stage 5.0 (TID 99) (172.18.0.7, executor 1, partition 41, PROCESS_LOCAL, 7608 bytes)
[2026-08-21T04:35:35.248+0000] {spark_submit.py:571} INFO - 26/08/21 04:35:35 INFO TaskSetManager: Finished task 38.0 in stage 5.0 (TID 97) in 89 ms on 172.18.0.7 (executor 1) (44/50)
[2026-08-21T04:35:35.271+0000] {spark_submit.py:571} INFO - 26/08/21 04:35:35 INFO TaskSetManager: Starting task 45.0 in stage 5.0 (TID 100) (172.18.0.7, executor 1, partition 45, PROCESS_LOCAL, 7608 bytes)
[2026-08-21T04:35:35.275+0000] {spark_submit.py:571} INFO - 26/08/21 04:35:35 INFO TaskSetManager: Finished task 40.0 in stage 5.0 (TID 98) in 94 ms on 172.18.0.7 (executor 1) (45/50)
[2026-08-21T04:35:35.384+0000] {spark_submit.py:571} INFO - 26/08/21 04:35:35 INFO TaskSetManager: Starting task 46.0 in stage 5.0 (TID 101) (172.18.0.7, executor 1, partition 46, PROCESS_LOCAL, 7608 bytes)
[2026-08-21T04:35:35.387+0000] {spark_submit.py:571} INFO - 26/08/21 04:35:35 INFO TaskSetManager: Finished task 41.0 in stage 5.0 (TID 99) in 141 ms on 172.18.0.7 (executor 1) (46/50)
[2026-08-21T04:35:35.402+0000] {spark_submit.py:571} INFO - 26/08/21 04:35:35 INFO TaskSetManager: Starting task 48.0 in stage 5.0 (TID 102) (172.18.0.7, executor 1, partition 48, PROCESS_LOCAL, 7608 bytes)
[2026-08-21T04:35:35.406+0000] {spark_submit.py:571} INFO - 26/08/21 04:35:35 INFO TaskSetManager: Finished task 45.0 in stage 5.0 (TID 100) in 135 ms on 172.18.0.7 (executor 1) (47/50)
[2026-08-21T04:35:35.441+0000] {spark_submit.py:571} INFO - 26/08/21 04:35:35 INFO TaskSetManager: Starting task 49.0 in stage 5.0 (TID 103) (172.18.0.7, executor 1, partition 49, PROCESS_LOCAL, 7608 bytes)
[2026-08-21T04:35:35.441+0000] {spark_submit.py:571} INFO - 26/08/21 04:35:35 INFO TaskSetManager: Finished task 48.0 in stage 5.0 (TID 102) in 40 ms on 172.18.0.7 (executor 1) (48/50)
[2026-08-21T04:35:35.459+0000] {spark_submit.py:571} INFO - 26/08/21 04:35:35 INFO TaskSetManager: Finished task 46.0 in stage 5.0 (TID 101) in 74 ms on 172.18.0.7 (executor 1) (49/50)
[2026-08-21T04:35:35.491+0000] {spark_submit.py:571} INFO - 26/08/21 04:35:35 INFO TaskSetManager: Finished task 49.0 in stage 5.0 (TID 103) in 50 ms on 172.18.0.7 (executor 1) (50/50)
[2026-08-21T04:35:35.494+0000] {spark_submit.py:571} INFO - 26/08/21 04:35:35 INFO TaskSchedulerImpl: Removed TaskSet 5.0, whose tasks have all completed, from pool
[2026-08-21T04:35:35.495+0000] {spark_submit.py:571} INFO - 26/08/21 04:35:35 INFO DAGScheduler: ShuffleMapStage 5 ($anonfun$recordDeltaOperationInternal$1 at DatabricksLogging.scala:128) finished in 2.587 s
[2026-08-21T04:35:35.495+0000] {spark_submit.py:571} INFO - 26/08/21 04:35:35 INFO DAGScheduler: looking for newly runnable stages
[2026-08-21T04:35:35.496+0000] {spark_submit.py:571} INFO - 26/08/21 04:35:35 INFO DAGScheduler: running: Set()
[2026-08-21T04:35:35.496+0000] {spark_submit.py:571} INFO - 26/08/21 04:35:35 INFO DAGScheduler: waiting: Set()
[2026-08-21T04:35:35.497+0000] {spark_submit.py:571} INFO - 26/08/21 04:35:35 INFO DAGScheduler: failed: Set()
[2026-08-21T04:35:35.541+0000] {spark_submit.py:571} INFO - 26/08/21 04:35:35 INFO SparkContext: Starting job: $anonfun$recordDeltaOperationInternal$1 at DatabricksLogging.scala:128
[2026-08-21T04:35:35.546+0000] {spark_submit.py:571} INFO - 26/08/21 04:35:35 INFO DAGScheduler: Got job 4 ($anonfun$recordDeltaOperationInternal$1 at DatabricksLogging.scala:128) with 1 output partitions
[2026-08-21T04:35:35.547+0000] {spark_submit.py:571} INFO - 26/08/21 04:35:35 INFO DAGScheduler: Final stage: ResultStage 8 ($anonfun$recordDeltaOperationInternal$1 at DatabricksLogging.scala:128)
[2026-08-21T04:35:35.547+0000] {spark_submit.py:571} INFO - 26/08/21 04:35:35 INFO DAGScheduler: Parents of final stage: List(ShuffleMapStage 7)
[2026-08-21T04:35:35.548+0000] {spark_submit.py:571} INFO - 26/08/21 04:35:35 INFO DAGScheduler: Missing parents: List()
[2026-08-21T04:35:35.548+0000] {spark_submit.py:571} INFO - 26/08/21 04:35:35 INFO DAGScheduler: Submitting ResultStage 8 (MapPartitionsRDD[22] at $anonfun$recordDeltaOperationInternal$1 at DatabricksLogging.scala:128), which has no missing parents
[2026-08-21T04:35:35.560+0000] {spark_submit.py:571} INFO - 26/08/21 04:35:35 INFO MemoryStore: Block broadcast_7 stored as values in memory (estimated size 533.4 KiB, free 432.7 MiB)
[2026-08-21T04:35:35.562+0000] {spark_submit.py:571} INFO - 26/08/21 04:35:35 INFO MemoryStore: Block broadcast_7_piece0 stored as bytes in memory (estimated size 124.5 KiB, free 432.6 MiB)
[2026-08-21T04:35:35.564+0000] {spark_submit.py:571} INFO - 26/08/21 04:35:35 INFO BlockManagerInfo: Added broadcast_7_piece0 in memory on c90a551abb73:39895 (size: 124.5 KiB, free: 434.1 MiB)
[2026-08-21T04:35:35.566+0000] {spark_submit.py:571} INFO - 26/08/21 04:35:35 INFO SparkContext: Created broadcast 7 from broadcast at DAGScheduler.scala:1585
[2026-08-21T04:35:35.566+0000] {spark_submit.py:571} INFO - 26/08/21 04:35:35 INFO DAGScheduler: Submitting 1 missing tasks from ResultStage 8 (MapPartitionsRDD[22] at $anonfun$recordDeltaOperationInternal$1 at DatabricksLogging.scala:128) (first 15 tasks are for partitions Vector(0))
[2026-08-21T04:35:35.566+0000] {spark_submit.py:571} INFO - 26/08/21 04:35:35 INFO TaskSchedulerImpl: Adding task set 8.0 with 1 tasks resource profile 0
[2026-08-21T04:35:35.567+0000] {spark_submit.py:571} INFO - 26/08/21 04:35:35 INFO TaskSetManager: Starting task 0.0 in stage 8.0 (TID 104) (172.18.0.6, executor 0, partition 0, NODE_LOCAL, 7619 bytes)
[2026-08-21T04:35:35.589+0000] {spark_submit.py:571} INFO - 26/08/21 04:35:35 INFO BlockManagerInfo: Added broadcast_7_piece0 in memory on 172.18.0.6:36781 (size: 124.5 KiB, free: 434.1 MiB)
[2026-08-21T04:35:35.604+0000] {spark_submit.py:571} INFO - 26/08/21 04:35:35 INFO MapOutputTrackerMasterEndpoint: Asked to send map output locations for shuffle 1 to 172.18.0.6:45820
[2026-08-21T04:35:35.712+0000] {spark_submit.py:571} INFO - 26/08/21 04:35:35 INFO TaskSetManager: Finished task 0.0 in stage 8.0 (TID 104) in 144 ms on 172.18.0.6 (executor 0) (1/1)
[2026-08-21T04:35:35.712+0000] {spark_submit.py:571} INFO - 26/08/21 04:35:35 INFO TaskSchedulerImpl: Removed TaskSet 8.0, whose tasks have all completed, from pool
[2026-08-21T04:35:35.715+0000] {spark_submit.py:571} INFO - 26/08/21 04:35:35 INFO DAGScheduler: ResultStage 8 ($anonfun$recordDeltaOperationInternal$1 at DatabricksLogging.scala:128) finished in 0.161 s
[2026-08-21T04:35:35.715+0000] {spark_submit.py:571} INFO - 26/08/21 04:35:35 INFO DAGScheduler: Job 4 is finished. Cancelling potential speculative or zombie tasks for this job
[2026-08-21T04:35:35.716+0000] {spark_submit.py:571} INFO - 26/08/21 04:35:35 INFO TaskSchedulerImpl: Killing all running tasks in stage 8: Stage finished
[2026-08-21T04:35:35.718+0000] {spark_submit.py:571} INFO - 26/08/21 04:35:35 INFO DAGScheduler: Job 4 finished: $anonfun$recordDeltaOperationInternal$1 at DatabricksLogging.scala:128, took 0.174539 s
[2026-08-21T04:35:35.825+0000] {spark_submit.py:571} INFO - 26/08/21 04:35:35 INFO CodeGenerator: Code generated in 89.252909 ms
[2026-08-21T04:35:35.831+0000] {spark_submit.py:571} INFO - 26/08/21 04:35:35 INFO Snapshot: [tableId=553802dd-42b6-4cf1-8af2-e0916230ea16] DELTA: Done
